2025-06-16 16:46:19,228 - root - INFO - Логирование успешно настроено
2025-06-16 16:46:19,228 - root - INFO - Бот запущен
2025-06-16 16:46:19,228 - root - INFO - Бот запущен
2025-06-16 16:46:41,052 - root - ERROR - Other error: TeleBot.send_message() missing 1 required positional argument: 'text'
2025-06-16 16:46:56,053 - root - INFO - Бот запущен
2025-06-16 16:47:15,082 - root - INFO - Бот запущен
2025-06-16 16:47:15,083 - root - ERROR - Other error: TeleBot.send_message() missing 1 required positional argument: 'text'
2025-06-16 16:47:23,988 - root - INFO - Логирование успешно настроено
2025-06-16 16:47:23,988 - root - INFO - Бот запущен
2025-06-16 16:47:23,992 - root - INFO - Бот запущен
2025-06-16 16:47:24,174 - root - ERROR - ConnectionError: ('Connection aborted.', ConnectionResetError(10054, 'Удаленный хост принудительно разорвал существующее подключение', None, 10054, None))
2025-06-16 16:47:29,575 - root - INFO - Логирование успешно настроено
2025-06-16 16:47:29,576 - root - INFO - Бот запущен
2025-06-16 16:47:29,576 - root - INFO - Бот запущен
2025-06-16 16:57:35,412 - root - ERROR - ConnectionError: ('Connection aborted.', ConnectionResetError(10054, 'Удаленный хост принудительно разорвал существующее подключение', None, 10054, None))
2025-06-16 16:57:55,413 - root - INFO - Бот запущен
2025-06-16 17:07:57,925 - root - ERROR - ConnectionError: ('Connection aborted.', ConnectionResetError(10054, 'Удаленный хост принудительно разорвал существующее подключение', None, 10054, None))
2025-06-16 17:07:59,473 - root - INFO - Логирование успешно настроено
2025-06-16 17:07:59,474 - root - INFO - Бот запущен
2025-06-16 17:07:59,474 - root - INFO - Бот запущен
2025-06-16 17:08:19,693 - root - ERROR - ConnectionError: HTTPSConnectionPool(host='api.telegram.org', port=443): Max retries exceeded with url: /bot8067610575:AAFjG0nG-vXZPZGlLMjXK_X_QyuuaG8gJvs/getUpdates?offset=1&timeout=20 (Caused by ConnectTimeoutError(<urllib3.connection.HTTPSConnection object at 0x000001D44CE28050>, 'Connection to api.telegram.org timed out. (connect timeout=20)'))
2025-06-16 17:08:40,581 - root - INFO - Логирование успешно настроено
2025-06-16 17:08:40,581 - root - INFO - Бот запущен
2025-06-16 17:08:40,581 - root - INFO - Бот запущен
2025-06-16 17:11:22,867 - root - INFO - Логирование успешно настроено
2025-06-16 17:11:22,868 - root - INFO - Бот запущен
2025-06-16 17:11:22,868 - root - INFO - Бот запущен
2025-06-16 17:13:49,629 - root - INFO - Логирование успешно настроено
2025-06-16 17:13:49,629 - root - INFO - Бот запущен
2025-06-16 17:13:49,629 - root - INFO - Бот запущен
2025-06-16 17:16:30,107 - root - INFO - Бот запущен
2025-06-16 17:20:21,776 - root - INFO - Логирование успешно настроено
2025-06-16 17:20:21,777 - root - INFO - Бот запущен
2025-06-16 17:20:21,777 - root - INFO - Бот запущен
2025-06-16 17:20:21,823 - root - INFO - Логирование успешно настроено
2025-06-16 17:20:21,823 - root - INFO - Бот запущен
2025-06-16 17:20:21,823 - root - INFO - Бот запущен
2025-06-16 17:20:24,041 - root - ERROR - ConnectionError: ('Connection aborted.', ConnectionResetError(10054, 'Удаленный хост принудительно разорвал существующее подключение', None, 10054, None))
2025-06-16 17:20:25,227 - TeleBot - ERROR - Threaded polling exception: A request to the Telegram API was unsuccessful. Error code: 409. Description: Conflict: terminated by other getUpdates request; make sure that only one bot instance is running
2025-06-16 17:20:25,227 - TeleBot - ERROR - Exception traceback:
Traceback (most recent call last):
  File "D:\Personal projects\Imperial_Lottery\.venv\Lib\site-packages\telebot\__init__.py", line 1234, in __threaded_polling
    polling_thread.raise_exceptions()
    ~~~~~~~~~~~~~~~~~~~~~~~~~~~~~~~^^
  File "D:\Personal projects\Imperial_Lottery\.venv\Lib\site-packages\telebot\util.py", line 111, in raise_exceptions
    raise self.exception_info
  File "D:\Personal projects\Imperial_Lottery\.venv\Lib\site-packages\telebot\util.py", line 93, in run
    task(*args, **kwargs)
    ~~~~^^^^^^^^^^^^^^^^^
  File "D:\Personal projects\Imperial_Lottery\.venv\Lib\site-packages\telebot\__init__.py", line 688, in __retrieve_updates
    updates = self.get_updates(offset=(self.last_update_id + 1),
                               allowed_updates=allowed_updates,
                               timeout=timeout, long_polling_timeout=long_polling_timeout)
  File "D:\Personal projects\Imperial_Lottery\.venv\Lib\site-packages\telebot\__init__.py", line 660, in get_updates
    json_updates = apihelper.get_updates(
        self.token, offset=offset, limit=limit, timeout=timeout, allowed_updates=allowed_updates,
        long_polling_timeout=long_polling_timeout)
  File "D:\Personal projects\Imperial_Lottery\.venv\Lib\site-packages\telebot\apihelper.py", line 332, in get_updates
    return _make_request(token, method_url, params=payload)
  File "D:\Personal projects\Imperial_Lottery\.venv\Lib\site-packages\telebot\apihelper.py", line 168, in _make_request
    json_result = _check_result(method_name, result)
  File "D:\Personal projects\Imperial_Lottery\.venv\Lib\site-packages\telebot\apihelper.py", line 195, in _check_result
    raise ApiTelegramException(method_name, result, result_json)
telebot.apihelper.ApiTelegramException: A request to the Telegram API was unsuccessful. Error code: 409. Description: Conflict: terminated by other getUpdates request; make sure that only one bot instance is running

2025-06-16 17:20:44,041 - root - INFO - Бот запущен
2025-06-16 17:20:44,258 - TeleBot - ERROR - Threaded polling exception: A request to the Telegram API was unsuccessful. Error code: 409. Description: Conflict: terminated by other getUpdates request; make sure that only one bot instance is running
2025-06-16 17:20:44,259 - TeleBot - ERROR - Exception traceback:
Traceback (most recent call last):
  File "D:\Personal projects\Imperial_Lottery\.venv\Lib\site-packages\telebot\__init__.py", line 1234, in __threaded_polling
    polling_thread.raise_exceptions()
    ~~~~~~~~~~~~~~~~~~~~~~~~~~~~~~~^^
  File "D:\Personal projects\Imperial_Lottery\.venv\Lib\site-packages\telebot\util.py", line 111, in raise_exceptions
    raise self.exception_info
  File "D:\Personal projects\Imperial_Lottery\.venv\Lib\site-packages\telebot\util.py", line 93, in run
    task(*args, **kwargs)
    ~~~~^^^^^^^^^^^^^^^^^
  File "D:\Personal projects\Imperial_Lottery\.venv\Lib\site-packages\telebot\__init__.py", line 688, in __retrieve_updates
    updates = self.get_updates(offset=(self.last_update_id + 1),
                               allowed_updates=allowed_updates,
                               timeout=timeout, long_polling_timeout=long_polling_timeout)
  File "D:\Personal projects\Imperial_Lottery\.venv\Lib\site-packages\telebot\__init__.py", line 660, in get_updates
    json_updates = apihelper.get_updates(
        self.token, offset=offset, limit=limit, timeout=timeout, allowed_updates=allowed_updates,
        long_polling_timeout=long_polling_timeout)
  File "D:\Personal projects\Imperial_Lottery\.venv\Lib\site-packages\telebot\apihelper.py", line 332, in get_updates
    return _make_request(token, method_url, params=payload)
  File "D:\Personal projects\Imperial_Lottery\.venv\Lib\site-packages\telebot\apihelper.py", line 168, in _make_request
    json_result = _check_result(method_name, result)
  File "D:\Personal projects\Imperial_Lottery\.venv\Lib\site-packages\telebot\apihelper.py", line 195, in _check_result
    raise ApiTelegramException(method_name, result, result_json)
telebot.apihelper.ApiTelegramException: A request to the Telegram API was unsuccessful. Error code: 409. Description: Conflict: terminated by other getUpdates request; make sure that only one bot instance is running

2025-06-16 17:20:47,574 - TeleBot - ERROR - Threaded polling exception: A request to the Telegram API was unsuccessful. Error code: 409. Description: Conflict: terminated by other getUpdates request; make sure that only one bot instance is running
2025-06-16 17:20:47,575 - TeleBot - ERROR - Exception traceback:
Traceback (most recent call last):
  File "D:\Personal projects\Imperial_Lottery\.venv\Lib\site-packages\telebot\__init__.py", line 1234, in __threaded_polling
    polling_thread.raise_exceptions()
    ~~~~~~~~~~~~~~~~~~~~~~~~~~~~~~~^^
  File "D:\Personal projects\Imperial_Lottery\.venv\Lib\site-packages\telebot\util.py", line 111, in raise_exceptions
    raise self.exception_info
  File "D:\Personal projects\Imperial_Lottery\.venv\Lib\site-packages\telebot\util.py", line 93, in run
    task(*args, **kwargs)
    ~~~~^^^^^^^^^^^^^^^^^
  File "D:\Personal projects\Imperial_Lottery\.venv\Lib\site-packages\telebot\__init__.py", line 688, in __retrieve_updates
    updates = self.get_updates(offset=(self.last_update_id + 1),
                               allowed_updates=allowed_updates,
                               timeout=timeout, long_polling_timeout=long_polling_timeout)
  File "D:\Personal projects\Imperial_Lottery\.venv\Lib\site-packages\telebot\__init__.py", line 660, in get_updates
    json_updates = apihelper.get_updates(
        self.token, offset=offset, limit=limit, timeout=timeout, allowed_updates=allowed_updates,
        long_polling_timeout=long_polling_timeout)
  File "D:\Personal projects\Imperial_Lottery\.venv\Lib\site-packages\telebot\apihelper.py", line 332, in get_updates
    return _make_request(token, method_url, params=payload)
  File "D:\Personal projects\Imperial_Lottery\.venv\Lib\site-packages\telebot\apihelper.py", line 168, in _make_request
    json_result = _check_result(method_name, result)
  File "D:\Personal projects\Imperial_Lottery\.venv\Lib\site-packages\telebot\apihelper.py", line 195, in _check_result
    raise ApiTelegramException(method_name, result, result_json)
telebot.apihelper.ApiTelegramException: A request to the Telegram API was unsuccessful. Error code: 409. Description: Conflict: terminated by other getUpdates request; make sure that only one bot instance is running

2025-06-16 17:20:47,892 - TeleBot - ERROR - Threaded polling exception: A request to the Telegram API was unsuccessful. Error code: 409. Description: Conflict: terminated by other getUpdates request; make sure that only one bot instance is running
2025-06-16 17:20:47,893 - TeleBot - ERROR - Exception traceback:
Traceback (most recent call last):
  File "D:\Personal projects\Imperial_Lottery\.venv\Lib\site-packages\telebot\__init__.py", line 1234, in __threaded_polling
    polling_thread.raise_exceptions()
    ~~~~~~~~~~~~~~~~~~~~~~~~~~~~~~~^^
  File "D:\Personal projects\Imperial_Lottery\.venv\Lib\site-packages\telebot\util.py", line 111, in raise_exceptions
    raise self.exception_info
  File "D:\Personal projects\Imperial_Lottery\.venv\Lib\site-packages\telebot\util.py", line 93, in run
    task(*args, **kwargs)
    ~~~~^^^^^^^^^^^^^^^^^
  File "D:\Personal projects\Imperial_Lottery\.venv\Lib\site-packages\telebot\__init__.py", line 688, in __retrieve_updates
    updates = self.get_updates(offset=(self.last_update_id + 1),
                               allowed_updates=allowed_updates,
                               timeout=timeout, long_polling_timeout=long_polling_timeout)
  File "D:\Personal projects\Imperial_Lottery\.venv\Lib\site-packages\telebot\__init__.py", line 660, in get_updates
    json_updates = apihelper.get_updates(
        self.token, offset=offset, limit=limit, timeout=timeout, allowed_updates=allowed_updates,
        long_polling_timeout=long_polling_timeout)
  File "D:\Personal projects\Imperial_Lottery\.venv\Lib\site-packages\telebot\apihelper.py", line 332, in get_updates
    return _make_request(token, method_url, params=payload)
  File "D:\Personal projects\Imperial_Lottery\.venv\Lib\site-packages\telebot\apihelper.py", line 168, in _make_request
    json_result = _check_result(method_name, result)
  File "D:\Personal projects\Imperial_Lottery\.venv\Lib\site-packages\telebot\apihelper.py", line 195, in _check_result
    raise ApiTelegramException(method_name, result, result_json)
telebot.apihelper.ApiTelegramException: A request to the Telegram API was unsuccessful. Error code: 409. Description: Conflict: terminated by other getUpdates request; make sure that only one bot instance is running

2025-06-16 17:20:51,456 - TeleBot - ERROR - Threaded polling exception: A request to the Telegram API was unsuccessful. Error code: 409. Description: Conflict: terminated by other getUpdates request; make sure that only one bot instance is running
2025-06-16 17:20:51,457 - TeleBot - ERROR - Exception traceback:
Traceback (most recent call last):
  File "D:\Personal projects\Imperial_Lottery\.venv\Lib\site-packages\telebot\__init__.py", line 1234, in __threaded_polling
    polling_thread.raise_exceptions()
    ~~~~~~~~~~~~~~~~~~~~~~~~~~~~~~~^^
  File "D:\Personal projects\Imperial_Lottery\.venv\Lib\site-packages\telebot\util.py", line 111, in raise_exceptions
    raise self.exception_info
  File "D:\Personal projects\Imperial_Lottery\.venv\Lib\site-packages\telebot\util.py", line 93, in run
    task(*args, **kwargs)
    ~~~~^^^^^^^^^^^^^^^^^
  File "D:\Personal projects\Imperial_Lottery\.venv\Lib\site-packages\telebot\__init__.py", line 688, in __retrieve_updates
    updates = self.get_updates(offset=(self.last_update_id + 1),
                               allowed_updates=allowed_updates,
                               timeout=timeout, long_polling_timeout=long_polling_timeout)
  File "D:\Personal projects\Imperial_Lottery\.venv\Lib\site-packages\telebot\__init__.py", line 660, in get_updates
    json_updates = apihelper.get_updates(
        self.token, offset=offset, limit=limit, timeout=timeout, allowed_updates=allowed_updates,
        long_polling_timeout=long_polling_timeout)
  File "D:\Personal projects\Imperial_Lottery\.venv\Lib\site-packages\telebot\apihelper.py", line 332, in get_updates
    return _make_request(token, method_url, params=payload)
  File "D:\Personal projects\Imperial_Lottery\.venv\Lib\site-packages\telebot\apihelper.py", line 168, in _make_request
    json_result = _check_result(method_name, result)
  File "D:\Personal projects\Imperial_Lottery\.venv\Lib\site-packages\telebot\apihelper.py", line 195, in _check_result
    raise ApiTelegramException(method_name, result, result_json)
telebot.apihelper.ApiTelegramException: A request to the Telegram API was unsuccessful. Error code: 409. Description: Conflict: terminated by other getUpdates request; make sure that only one bot instance is running

2025-06-16 17:20:52,020 - TeleBot - ERROR - Threaded polling exception: A request to the Telegram API was unsuccessful. Error code: 409. Description: Conflict: terminated by other getUpdates request; make sure that only one bot instance is running
2025-06-16 17:20:52,021 - TeleBot - ERROR - Exception traceback:
Traceback (most recent call last):
  File "D:\Personal projects\Imperial_Lottery\.venv\Lib\site-packages\telebot\__init__.py", line 1234, in __threaded_polling
    polling_thread.raise_exceptions()
    ~~~~~~~~~~~~~~~~~~~~~~~~~~~~~~~^^
  File "D:\Personal projects\Imperial_Lottery\.venv\Lib\site-packages\telebot\util.py", line 111, in raise_exceptions
    raise self.exception_info
  File "D:\Personal projects\Imperial_Lottery\.venv\Lib\site-packages\telebot\util.py", line 93, in run
    task(*args, **kwargs)
    ~~~~^^^^^^^^^^^^^^^^^
  File "D:\Personal projects\Imperial_Lottery\.venv\Lib\site-packages\telebot\__init__.py", line 688, in __retrieve_updates
    updates = self.get_updates(offset=(self.last_update_id + 1),
                               allowed_updates=allowed_updates,
                               timeout=timeout, long_polling_timeout=long_polling_timeout)
  File "D:\Personal projects\Imperial_Lottery\.venv\Lib\site-packages\telebot\__init__.py", line 660, in get_updates
    json_updates = apihelper.get_updates(
        self.token, offset=offset, limit=limit, timeout=timeout, allowed_updates=allowed_updates,
        long_polling_timeout=long_polling_timeout)
  File "D:\Personal projects\Imperial_Lottery\.venv\Lib\site-packages\telebot\apihelper.py", line 332, in get_updates
    return _make_request(token, method_url, params=payload)
  File "D:\Personal projects\Imperial_Lottery\.venv\Lib\site-packages\telebot\apihelper.py", line 168, in _make_request
    json_result = _check_result(method_name, result)
  File "D:\Personal projects\Imperial_Lottery\.venv\Lib\site-packages\telebot\apihelper.py", line 195, in _check_result
    raise ApiTelegramException(method_name, result, result_json)
telebot.apihelper.ApiTelegramException: A request to the Telegram API was unsuccessful. Error code: 409. Description: Conflict: terminated by other getUpdates request; make sure that only one bot instance is running

2025-06-16 17:20:56,084 - TeleBot - ERROR - Threaded polling exception: A request to the Telegram API was unsuccessful. Error code: 409. Description: Conflict: terminated by other getUpdates request; make sure that only one bot instance is running
2025-06-16 17:20:56,084 - TeleBot - ERROR - Exception traceback:
Traceback (most recent call last):
  File "D:\Personal projects\Imperial_Lottery\.venv\Lib\site-packages\telebot\__init__.py", line 1234, in __threaded_polling
    polling_thread.raise_exceptions()
    ~~~~~~~~~~~~~~~~~~~~~~~~~~~~~~~^^
  File "D:\Personal projects\Imperial_Lottery\.venv\Lib\site-packages\telebot\util.py", line 111, in raise_exceptions
    raise self.exception_info
  File "D:\Personal projects\Imperial_Lottery\.venv\Lib\site-packages\telebot\util.py", line 93, in run
    task(*args, **kwargs)
    ~~~~^^^^^^^^^^^^^^^^^
  File "D:\Personal projects\Imperial_Lottery\.venv\Lib\site-packages\telebot\__init__.py", line 688, in __retrieve_updates
    updates = self.get_updates(offset=(self.last_update_id + 1),
                               allowed_updates=allowed_updates,
                               timeout=timeout, long_polling_timeout=long_polling_timeout)
  File "D:\Personal projects\Imperial_Lottery\.venv\Lib\site-packages\telebot\__init__.py", line 660, in get_updates
    json_updates = apihelper.get_updates(
        self.token, offset=offset, limit=limit, timeout=timeout, allowed_updates=allowed_updates,
        long_polling_timeout=long_polling_timeout)
  File "D:\Personal projects\Imperial_Lottery\.venv\Lib\site-packages\telebot\apihelper.py", line 332, in get_updates
    return _make_request(token, method_url, params=payload)
  File "D:\Personal projects\Imperial_Lottery\.venv\Lib\site-packages\telebot\apihelper.py", line 168, in _make_request
    json_result = _check_result(method_name, result)
  File "D:\Personal projects\Imperial_Lottery\.venv\Lib\site-packages\telebot\apihelper.py", line 195, in _check_result
    raise ApiTelegramException(method_name, result, result_json)
telebot.apihelper.ApiTelegramException: A request to the Telegram API was unsuccessful. Error code: 409. Description: Conflict: terminated by other getUpdates request; make sure that only one bot instance is running

2025-06-16 17:20:57,152 - TeleBot - ERROR - Threaded polling exception: A request to the Telegram API was unsuccessful. Error code: 409. Description: Conflict: terminated by other getUpdates request; make sure that only one bot instance is running
2025-06-16 17:20:57,153 - TeleBot - ERROR - Exception traceback:
Traceback (most recent call last):
  File "D:\Personal projects\Imperial_Lottery\.venv\Lib\site-packages\telebot\__init__.py", line 1234, in __threaded_polling
    polling_thread.raise_exceptions()
    ~~~~~~~~~~~~~~~~~~~~~~~~~~~~~~~^^
  File "D:\Personal projects\Imperial_Lottery\.venv\Lib\site-packages\telebot\util.py", line 111, in raise_exceptions
    raise self.exception_info
  File "D:\Personal projects\Imperial_Lottery\.venv\Lib\site-packages\telebot\util.py", line 93, in run
    task(*args, **kwargs)
    ~~~~^^^^^^^^^^^^^^^^^
  File "D:\Personal projects\Imperial_Lottery\.venv\Lib\site-packages\telebot\__init__.py", line 688, in __retrieve_updates
    updates = self.get_updates(offset=(self.last_update_id + 1),
                               allowed_updates=allowed_updates,
                               timeout=timeout, long_polling_timeout=long_polling_timeout)
  File "D:\Personal projects\Imperial_Lottery\.venv\Lib\site-packages\telebot\__init__.py", line 660, in get_updates
    json_updates = apihelper.get_updates(
        self.token, offset=offset, limit=limit, timeout=timeout, allowed_updates=allowed_updates,
        long_polling_timeout=long_polling_timeout)
  File "D:\Personal projects\Imperial_Lottery\.venv\Lib\site-packages\telebot\apihelper.py", line 332, in get_updates
    return _make_request(token, method_url, params=payload)
  File "D:\Personal projects\Imperial_Lottery\.venv\Lib\site-packages\telebot\apihelper.py", line 168, in _make_request
    json_result = _check_result(method_name, result)
  File "D:\Personal projects\Imperial_Lottery\.venv\Lib\site-packages\telebot\apihelper.py", line 195, in _check_result
    raise ApiTelegramException(method_name, result, result_json)
telebot.apihelper.ApiTelegramException: A request to the Telegram API was unsuccessful. Error code: 409. Description: Conflict: terminated by other getUpdates request; make sure that only one bot instance is running

2025-06-16 17:21:02,221 - TeleBot - ERROR - Threaded polling exception: A request to the Telegram API was unsuccessful. Error code: 409. Description: Conflict: terminated by other getUpdates request; make sure that only one bot instance is running
2025-06-16 17:21:02,222 - TeleBot - ERROR - Exception traceback:
Traceback (most recent call last):
  File "D:\Personal projects\Imperial_Lottery\.venv\Lib\site-packages\telebot\__init__.py", line 1234, in __threaded_polling
    polling_thread.raise_exceptions()
    ~~~~~~~~~~~~~~~~~~~~~~~~~~~~~~~^^
  File "D:\Personal projects\Imperial_Lottery\.venv\Lib\site-packages\telebot\util.py", line 111, in raise_exceptions
    raise self.exception_info
  File "D:\Personal projects\Imperial_Lottery\.venv\Lib\site-packages\telebot\util.py", line 93, in run
    task(*args, **kwargs)
    ~~~~^^^^^^^^^^^^^^^^^
  File "D:\Personal projects\Imperial_Lottery\.venv\Lib\site-packages\telebot\__init__.py", line 688, in __retrieve_updates
    updates = self.get_updates(offset=(self.last_update_id + 1),
                               allowed_updates=allowed_updates,
                               timeout=timeout, long_polling_timeout=long_polling_timeout)
  File "D:\Personal projects\Imperial_Lottery\.venv\Lib\site-packages\telebot\__init__.py", line 660, in get_updates
    json_updates = apihelper.get_updates(
        self.token, offset=offset, limit=limit, timeout=timeout, allowed_updates=allowed_updates,
        long_polling_timeout=long_polling_timeout)
  File "D:\Personal projects\Imperial_Lottery\.venv\Lib\site-packages\telebot\apihelper.py", line 332, in get_updates
    return _make_request(token, method_url, params=payload)
  File "D:\Personal projects\Imperial_Lottery\.venv\Lib\site-packages\telebot\apihelper.py", line 168, in _make_request
    json_result = _check_result(method_name, result)
  File "D:\Personal projects\Imperial_Lottery\.venv\Lib\site-packages\telebot\apihelper.py", line 195, in _check_result
    raise ApiTelegramException(method_name, result, result_json)
telebot.apihelper.ApiTelegramException: A request to the Telegram API was unsuccessful. Error code: 409. Description: Conflict: terminated by other getUpdates request; make sure that only one bot instance is running

2025-06-16 17:21:04,288 - TeleBot - ERROR - Threaded polling exception: A request to the Telegram API was unsuccessful. Error code: 409. Description: Conflict: terminated by other getUpdates request; make sure that only one bot instance is running
2025-06-16 17:21:04,289 - TeleBot - ERROR - Exception traceback:
Traceback (most recent call last):
  File "D:\Personal projects\Imperial_Lottery\.venv\Lib\site-packages\telebot\__init__.py", line 1234, in __threaded_polling
    polling_thread.raise_exceptions()
    ~~~~~~~~~~~~~~~~~~~~~~~~~~~~~~~^^
  File "D:\Personal projects\Imperial_Lottery\.venv\Lib\site-packages\telebot\util.py", line 111, in raise_exceptions
    raise self.exception_info
  File "D:\Personal projects\Imperial_Lottery\.venv\Lib\site-packages\telebot\util.py", line 93, in run
    task(*args, **kwargs)
    ~~~~^^^^^^^^^^^^^^^^^
  File "D:\Personal projects\Imperial_Lottery\.venv\Lib\site-packages\telebot\__init__.py", line 688, in __retrieve_updates
    updates = self.get_updates(offset=(self.last_update_id + 1),
                               allowed_updates=allowed_updates,
                               timeout=timeout, long_polling_timeout=long_polling_timeout)
  File "D:\Personal projects\Imperial_Lottery\.venv\Lib\site-packages\telebot\__init__.py", line 660, in get_updates
    json_updates = apihelper.get_updates(
        self.token, offset=offset, limit=limit, timeout=timeout, allowed_updates=allowed_updates,
        long_polling_timeout=long_polling_timeout)
  File "D:\Personal projects\Imperial_Lottery\.venv\Lib\site-packages\telebot\apihelper.py", line 332, in get_updates
    return _make_request(token, method_url, params=payload)
  File "D:\Personal projects\Imperial_Lottery\.venv\Lib\site-packages\telebot\apihelper.py", line 168, in _make_request
    json_result = _check_result(method_name, result)
  File "D:\Personal projects\Imperial_Lottery\.venv\Lib\site-packages\telebot\apihelper.py", line 195, in _check_result
    raise ApiTelegramException(method_name, result, result_json)
telebot.apihelper.ApiTelegramException: A request to the Telegram API was unsuccessful. Error code: 409. Description: Conflict: terminated by other getUpdates request; make sure that only one bot instance is running

2025-06-16 17:21:08,352 - TeleBot - ERROR - Threaded polling exception: A request to the Telegram API was unsuccessful. Error code: 409. Description: Conflict: terminated by other getUpdates request; make sure that only one bot instance is running
2025-06-16 17:21:08,352 - TeleBot - ERROR - Exception traceback:
Traceback (most recent call last):
  File "D:\Personal projects\Imperial_Lottery\.venv\Lib\site-packages\telebot\__init__.py", line 1234, in __threaded_polling
    polling_thread.raise_exceptions()
    ~~~~~~~~~~~~~~~~~~~~~~~~~~~~~~~^^
  File "D:\Personal projects\Imperial_Lottery\.venv\Lib\site-packages\telebot\util.py", line 111, in raise_exceptions
    raise self.exception_info
  File "D:\Personal projects\Imperial_Lottery\.venv\Lib\site-packages\telebot\util.py", line 93, in run
    task(*args, **kwargs)
    ~~~~^^^^^^^^^^^^^^^^^
  File "D:\Personal projects\Imperial_Lottery\.venv\Lib\site-packages\telebot\__init__.py", line 688, in __retrieve_updates
    updates = self.get_updates(offset=(self.last_update_id + 1),
                               allowed_updates=allowed_updates,
                               timeout=timeout, long_polling_timeout=long_polling_timeout)
  File "D:\Personal projects\Imperial_Lottery\.venv\Lib\site-packages\telebot\__init__.py", line 660, in get_updates
    json_updates = apihelper.get_updates(
        self.token, offset=offset, limit=limit, timeout=timeout, allowed_updates=allowed_updates,
        long_polling_timeout=long_polling_timeout)
  File "D:\Personal projects\Imperial_Lottery\.venv\Lib\site-packages\telebot\apihelper.py", line 332, in get_updates
    return _make_request(token, method_url, params=payload)
  File "D:\Personal projects\Imperial_Lottery\.venv\Lib\site-packages\telebot\apihelper.py", line 168, in _make_request
    json_result = _check_result(method_name, result)
  File "D:\Personal projects\Imperial_Lottery\.venv\Lib\site-packages\telebot\apihelper.py", line 195, in _check_result
    raise ApiTelegramException(method_name, result, result_json)
telebot.apihelper.ApiTelegramException: A request to the Telegram API was unsuccessful. Error code: 409. Description: Conflict: terminated by other getUpdates request; make sure that only one bot instance is running

2025-06-16 17:21:12,420 - TeleBot - ERROR - Threaded polling exception: A request to the Telegram API was unsuccessful. Error code: 409. Description: Conflict: terminated by other getUpdates request; make sure that only one bot instance is running
2025-06-16 17:21:12,422 - TeleBot - ERROR - Exception traceback:
Traceback (most recent call last):
  File "D:\Personal projects\Imperial_Lottery\.venv\Lib\site-packages\telebot\__init__.py", line 1234, in __threaded_polling
    polling_thread.raise_exceptions()
    ~~~~~~~~~~~~~~~~~~~~~~~~~~~~~~~^^
  File "D:\Personal projects\Imperial_Lottery\.venv\Lib\site-packages\telebot\util.py", line 111, in raise_exceptions
    raise self.exception_info
  File "D:\Personal projects\Imperial_Lottery\.venv\Lib\site-packages\telebot\util.py", line 93, in run
    task(*args, **kwargs)
    ~~~~^^^^^^^^^^^^^^^^^
  File "D:\Personal projects\Imperial_Lottery\.venv\Lib\site-packages\telebot\__init__.py", line 688, in __retrieve_updates
    updates = self.get_updates(offset=(self.last_update_id + 1),
                               allowed_updates=allowed_updates,
                               timeout=timeout, long_polling_timeout=long_polling_timeout)
  File "D:\Personal projects\Imperial_Lottery\.venv\Lib\site-packages\telebot\__init__.py", line 660, in get_updates
    json_updates = apihelper.get_updates(
        self.token, offset=offset, limit=limit, timeout=timeout, allowed_updates=allowed_updates,
        long_polling_timeout=long_polling_timeout)
  File "D:\Personal projects\Imperial_Lottery\.venv\Lib\site-packages\telebot\apihelper.py", line 332, in get_updates
    return _make_request(token, method_url, params=payload)
  File "D:\Personal projects\Imperial_Lottery\.venv\Lib\site-packages\telebot\apihelper.py", line 168, in _make_request
    json_result = _check_result(method_name, result)
  File "D:\Personal projects\Imperial_Lottery\.venv\Lib\site-packages\telebot\apihelper.py", line 195, in _check_result
    raise ApiTelegramException(method_name, result, result_json)
telebot.apihelper.ApiTelegramException: A request to the Telegram API was unsuccessful. Error code: 409. Description: Conflict: terminated by other getUpdates request; make sure that only one bot instance is running

2025-06-16 17:21:20,487 - TeleBot - ERROR - Threaded polling exception: A request to the Telegram API was unsuccessful. Error code: 409. Description: Conflict: terminated by other getUpdates request; make sure that only one bot instance is running
2025-06-16 17:21:20,488 - TeleBot - ERROR - Exception traceback:
Traceback (most recent call last):
  File "D:\Personal projects\Imperial_Lottery\.venv\Lib\site-packages\telebot\__init__.py", line 1234, in __threaded_polling
    polling_thread.raise_exceptions()
    ~~~~~~~~~~~~~~~~~~~~~~~~~~~~~~~^^
  File "D:\Personal projects\Imperial_Lottery\.venv\Lib\site-packages\telebot\util.py", line 111, in raise_exceptions
    raise self.exception_info
  File "D:\Personal projects\Imperial_Lottery\.venv\Lib\site-packages\telebot\util.py", line 93, in run
    task(*args, **kwargs)
    ~~~~^^^^^^^^^^^^^^^^^
  File "D:\Personal projects\Imperial_Lottery\.venv\Lib\site-packages\telebot\__init__.py", line 688, in __retrieve_updates
    updates = self.get_updates(offset=(self.last_update_id + 1),
                               allowed_updates=allowed_updates,
                               timeout=timeout, long_polling_timeout=long_polling_timeout)
  File "D:\Personal projects\Imperial_Lottery\.venv\Lib\site-packages\telebot\__init__.py", line 660, in get_updates
    json_updates = apihelper.get_updates(
        self.token, offset=offset, limit=limit, timeout=timeout, allowed_updates=allowed_updates,
        long_polling_timeout=long_polling_timeout)
  File "D:\Personal projects\Imperial_Lottery\.venv\Lib\site-packages\telebot\apihelper.py", line 332, in get_updates
    return _make_request(token, method_url, params=payload)
  File "D:\Personal projects\Imperial_Lottery\.venv\Lib\site-packages\telebot\apihelper.py", line 168, in _make_request
    json_result = _check_result(method_name, result)
  File "D:\Personal projects\Imperial_Lottery\.venv\Lib\site-packages\telebot\apihelper.py", line 195, in _check_result
    raise ApiTelegramException(method_name, result, result_json)
telebot.apihelper.ApiTelegramException: A request to the Telegram API was unsuccessful. Error code: 409. Description: Conflict: terminated by other getUpdates request; make sure that only one bot instance is running

2025-06-16 17:21:28,552 - TeleBot - ERROR - Threaded polling exception: A request to the Telegram API was unsuccessful. Error code: 409. Description: Conflict: terminated by other getUpdates request; make sure that only one bot instance is running
2025-06-16 17:21:28,553 - TeleBot - ERROR - Exception traceback:
Traceback (most recent call last):
  File "D:\Personal projects\Imperial_Lottery\.venv\Lib\site-packages\telebot\__init__.py", line 1234, in __threaded_polling
    polling_thread.raise_exceptions()
    ~~~~~~~~~~~~~~~~~~~~~~~~~~~~~~~^^
  File "D:\Personal projects\Imperial_Lottery\.venv\Lib\site-packages\telebot\util.py", line 111, in raise_exceptions
    raise self.exception_info
  File "D:\Personal projects\Imperial_Lottery\.venv\Lib\site-packages\telebot\util.py", line 93, in run
    task(*args, **kwargs)
    ~~~~^^^^^^^^^^^^^^^^^
  File "D:\Personal projects\Imperial_Lottery\.venv\Lib\site-packages\telebot\__init__.py", line 688, in __retrieve_updates
    updates = self.get_updates(offset=(self.last_update_id + 1),
                               allowed_updates=allowed_updates,
                               timeout=timeout, long_polling_timeout=long_polling_timeout)
  File "D:\Personal projects\Imperial_Lottery\.venv\Lib\site-packages\telebot\__init__.py", line 660, in get_updates
    json_updates = apihelper.get_updates(
        self.token, offset=offset, limit=limit, timeout=timeout, allowed_updates=allowed_updates,
        long_polling_timeout=long_polling_timeout)
  File "D:\Personal projects\Imperial_Lottery\.venv\Lib\site-packages\telebot\apihelper.py", line 332, in get_updates
    return _make_request(token, method_url, params=payload)
  File "D:\Personal projects\Imperial_Lottery\.venv\Lib\site-packages\telebot\apihelper.py", line 168, in _make_request
    json_result = _check_result(method_name, result)
  File "D:\Personal projects\Imperial_Lottery\.venv\Lib\site-packages\telebot\apihelper.py", line 195, in _check_result
    raise ApiTelegramException(method_name, result, result_json)
telebot.apihelper.ApiTelegramException: A request to the Telegram API was unsuccessful. Error code: 409. Description: Conflict: terminated by other getUpdates request; make sure that only one bot instance is running

2025-06-16 17:21:34,155 - root - INFO - Логирование успешно настроено
2025-06-16 17:21:34,155 - root - INFO - Бот запущен
2025-06-16 17:21:34,155 - root - INFO - Бот запущен
2025-06-16 17:21:34,558 - root - ERROR - ConnectionError: ('Connection aborted.', ConnectionResetError(10054, 'Удаленный хост принудительно разорвал существующее подключение', None, 10054, None))
2025-06-16 17:21:44,618 - TeleBot - ERROR - Threaded polling exception: A request to the Telegram API was unsuccessful. Error code: 409. Description: Conflict: terminated by other getUpdates request; make sure that only one bot instance is running
2025-06-16 17:21:44,619 - TeleBot - ERROR - Exception traceback:
Traceback (most recent call last):
  File "D:\Personal projects\Imperial_Lottery\.venv\Lib\site-packages\telebot\__init__.py", line 1234, in __threaded_polling
    polling_thread.raise_exceptions()
    ~~~~~~~~~~~~~~~~~~~~~~~~~~~~~~~^^
  File "D:\Personal projects\Imperial_Lottery\.venv\Lib\site-packages\telebot\util.py", line 111, in raise_exceptions
    raise self.exception_info
  File "D:\Personal projects\Imperial_Lottery\.venv\Lib\site-packages\telebot\util.py", line 93, in run
    task(*args, **kwargs)
    ~~~~^^^^^^^^^^^^^^^^^
  File "D:\Personal projects\Imperial_Lottery\.venv\Lib\site-packages\telebot\__init__.py", line 688, in __retrieve_updates
    updates = self.get_updates(offset=(self.last_update_id + 1),
                               allowed_updates=allowed_updates,
                               timeout=timeout, long_polling_timeout=long_polling_timeout)
  File "D:\Personal projects\Imperial_Lottery\.venv\Lib\site-packages\telebot\__init__.py", line 660, in get_updates
    json_updates = apihelper.get_updates(
        self.token, offset=offset, limit=limit, timeout=timeout, allowed_updates=allowed_updates,
        long_polling_timeout=long_polling_timeout)
  File "D:\Personal projects\Imperial_Lottery\.venv\Lib\site-packages\telebot\apihelper.py", line 332, in get_updates
    return _make_request(token, method_url, params=payload)
  File "D:\Personal projects\Imperial_Lottery\.venv\Lib\site-packages\telebot\apihelper.py", line 168, in _make_request
    json_result = _check_result(method_name, result)
  File "D:\Personal projects\Imperial_Lottery\.venv\Lib\site-packages\telebot\apihelper.py", line 195, in _check_result
    raise ApiTelegramException(method_name, result, result_json)
telebot.apihelper.ApiTelegramException: A request to the Telegram API was unsuccessful. Error code: 409. Description: Conflict: terminated by other getUpdates request; make sure that only one bot instance is running

2025-06-16 17:21:47,933 - TeleBot - ERROR - Threaded polling exception: A request to the Telegram API was unsuccessful. Error code: 409. Description: Conflict: terminated by other getUpdates request; make sure that only one bot instance is running
2025-06-16 17:21:47,933 - TeleBot - ERROR - Exception traceback:
Traceback (most recent call last):
  File "D:\Personal projects\Imperial_Lottery\.venv\Lib\site-packages\telebot\__init__.py", line 1234, in __threaded_polling
    polling_thread.raise_exceptions()
    ~~~~~~~~~~~~~~~~~~~~~~~~~~~~~~~^^
  File "D:\Personal projects\Imperial_Lottery\.venv\Lib\site-packages\telebot\util.py", line 111, in raise_exceptions
    raise self.exception_info
  File "D:\Personal projects\Imperial_Lottery\.venv\Lib\site-packages\telebot\util.py", line 93, in run
    task(*args, **kwargs)
    ~~~~^^^^^^^^^^^^^^^^^
  File "D:\Personal projects\Imperial_Lottery\.venv\Lib\site-packages\telebot\__init__.py", line 688, in __retrieve_updates
    updates = self.get_updates(offset=(self.last_update_id + 1),
                               allowed_updates=allowed_updates,
                               timeout=timeout, long_polling_timeout=long_polling_timeout)
  File "D:\Personal projects\Imperial_Lottery\.venv\Lib\site-packages\telebot\__init__.py", line 660, in get_updates
    json_updates = apihelper.get_updates(
        self.token, offset=offset, limit=limit, timeout=timeout, allowed_updates=allowed_updates,
        long_polling_timeout=long_polling_timeout)
  File "D:\Personal projects\Imperial_Lottery\.venv\Lib\site-packages\telebot\apihelper.py", line 332, in get_updates
    return _make_request(token, method_url, params=payload)
  File "D:\Personal projects\Imperial_Lottery\.venv\Lib\site-packages\telebot\apihelper.py", line 168, in _make_request
    json_result = _check_result(method_name, result)
  File "D:\Personal projects\Imperial_Lottery\.venv\Lib\site-packages\telebot\apihelper.py", line 195, in _check_result
    raise ApiTelegramException(method_name, result, result_json)
telebot.apihelper.ApiTelegramException: A request to the Telegram API was unsuccessful. Error code: 409. Description: Conflict: terminated by other getUpdates request; make sure that only one bot instance is running

2025-06-16 17:21:54,560 - root - INFO - Бот запущен
2025-06-16 17:21:54,752 - root - ERROR - ConnectionError: ('Connection aborted.', ConnectionResetError(10054, 'Удаленный хост принудительно разорвал существующее подключение', None, 10054, None))
2025-06-16 17:22:19,753 - root - INFO - Бот запущен
2025-06-16 17:22:19,937 - TeleBot - ERROR - Threaded polling exception: A request to the Telegram API was unsuccessful. Error code: 409. Description: Conflict: terminated by other getUpdates request; make sure that only one bot instance is running
2025-06-16 17:22:19,938 - TeleBot - ERROR - Exception traceback:
Traceback (most recent call last):
  File "D:\Personal projects\Imperial_Lottery\.venv\Lib\site-packages\telebot\__init__.py", line 1234, in __threaded_polling
    polling_thread.raise_exceptions()
    ~~~~~~~~~~~~~~~~~~~~~~~~~~~~~~~^^
  File "D:\Personal projects\Imperial_Lottery\.venv\Lib\site-packages\telebot\util.py", line 111, in raise_exceptions
    raise self.exception_info
  File "D:\Personal projects\Imperial_Lottery\.venv\Lib\site-packages\telebot\util.py", line 93, in run
    task(*args, **kwargs)
    ~~~~^^^^^^^^^^^^^^^^^
  File "D:\Personal projects\Imperial_Lottery\.venv\Lib\site-packages\telebot\__init__.py", line 688, in __retrieve_updates
    updates = self.get_updates(offset=(self.last_update_id + 1),
                               allowed_updates=allowed_updates,
                               timeout=timeout, long_polling_timeout=long_polling_timeout)
  File "D:\Personal projects\Imperial_Lottery\.venv\Lib\site-packages\telebot\__init__.py", line 660, in get_updates
    json_updates = apihelper.get_updates(
        self.token, offset=offset, limit=limit, timeout=timeout, allowed_updates=allowed_updates,
        long_polling_timeout=long_polling_timeout)
  File "D:\Personal projects\Imperial_Lottery\.venv\Lib\site-packages\telebot\apihelper.py", line 332, in get_updates
    return _make_request(token, method_url, params=payload)
  File "D:\Personal projects\Imperial_Lottery\.venv\Lib\site-packages\telebot\apihelper.py", line 168, in _make_request
    json_result = _check_result(method_name, result)
  File "D:\Personal projects\Imperial_Lottery\.venv\Lib\site-packages\telebot\apihelper.py", line 195, in _check_result
    raise ApiTelegramException(method_name, result, result_json)
telebot.apihelper.ApiTelegramException: A request to the Telegram API was unsuccessful. Error code: 409. Description: Conflict: terminated by other getUpdates request; make sure that only one bot instance is running

2025-06-16 17:22:22,996 - TeleBot - ERROR - Threaded polling exception: A request to the Telegram API was unsuccessful. Error code: 409. Description: Conflict: terminated by other getUpdates request; make sure that only one bot instance is running
2025-06-16 17:22:22,997 - TeleBot - ERROR - Exception traceback:
Traceback (most recent call last):
  File "D:\Personal projects\Imperial_Lottery\.venv\Lib\site-packages\telebot\__init__.py", line 1234, in __threaded_polling
    polling_thread.raise_exceptions()
    ~~~~~~~~~~~~~~~~~~~~~~~~~~~~~~~^^
  File "D:\Personal projects\Imperial_Lottery\.venv\Lib\site-packages\telebot\util.py", line 111, in raise_exceptions
    raise self.exception_info
  File "D:\Personal projects\Imperial_Lottery\.venv\Lib\site-packages\telebot\util.py", line 93, in run
    task(*args, **kwargs)
    ~~~~^^^^^^^^^^^^^^^^^
  File "D:\Personal projects\Imperial_Lottery\.venv\Lib\site-packages\telebot\__init__.py", line 688, in __retrieve_updates
    updates = self.get_updates(offset=(self.last_update_id + 1),
                               allowed_updates=allowed_updates,
                               timeout=timeout, long_polling_timeout=long_polling_timeout)
  File "D:\Personal projects\Imperial_Lottery\.venv\Lib\site-packages\telebot\__init__.py", line 660, in get_updates
    json_updates = apihelper.get_updates(
        self.token, offset=offset, limit=limit, timeout=timeout, allowed_updates=allowed_updates,
        long_polling_timeout=long_polling_timeout)
  File "D:\Personal projects\Imperial_Lottery\.venv\Lib\site-packages\telebot\apihelper.py", line 332, in get_updates
    return _make_request(token, method_url, params=payload)
  File "D:\Personal projects\Imperial_Lottery\.venv\Lib\site-packages\telebot\apihelper.py", line 168, in _make_request
    json_result = _check_result(method_name, result)
  File "D:\Personal projects\Imperial_Lottery\.venv\Lib\site-packages\telebot\apihelper.py", line 195, in _check_result
    raise ApiTelegramException(method_name, result, result_json)
telebot.apihelper.ApiTelegramException: A request to the Telegram API was unsuccessful. Error code: 409. Description: Conflict: terminated by other getUpdates request; make sure that only one bot instance is running

2025-06-16 17:22:23,258 - TeleBot - ERROR - Threaded polling exception: A request to the Telegram API was unsuccessful. Error code: 409. Description: Conflict: terminated by other getUpdates request; make sure that only one bot instance is running
2025-06-16 17:22:23,259 - TeleBot - ERROR - Exception traceback:
Traceback (most recent call last):
  File "D:\Personal projects\Imperial_Lottery\.venv\Lib\site-packages\telebot\__init__.py", line 1234, in __threaded_polling
    polling_thread.raise_exceptions()
    ~~~~~~~~~~~~~~~~~~~~~~~~~~~~~~~^^
  File "D:\Personal projects\Imperial_Lottery\.venv\Lib\site-packages\telebot\util.py", line 111, in raise_exceptions
    raise self.exception_info
  File "D:\Personal projects\Imperial_Lottery\.venv\Lib\site-packages\telebot\util.py", line 93, in run
    task(*args, **kwargs)
    ~~~~^^^^^^^^^^^^^^^^^
  File "D:\Personal projects\Imperial_Lottery\.venv\Lib\site-packages\telebot\__init__.py", line 688, in __retrieve_updates
    updates = self.get_updates(offset=(self.last_update_id + 1),
                               allowed_updates=allowed_updates,
                               timeout=timeout, long_polling_timeout=long_polling_timeout)
  File "D:\Personal projects\Imperial_Lottery\.venv\Lib\site-packages\telebot\__init__.py", line 660, in get_updates
    json_updates = apihelper.get_updates(
        self.token, offset=offset, limit=limit, timeout=timeout, allowed_updates=allowed_updates,
        long_polling_timeout=long_polling_timeout)
  File "D:\Personal projects\Imperial_Lottery\.venv\Lib\site-packages\telebot\apihelper.py", line 332, in get_updates
    return _make_request(token, method_url, params=payload)
  File "D:\Personal projects\Imperial_Lottery\.venv\Lib\site-packages\telebot\apihelper.py", line 168, in _make_request
    json_result = _check_result(method_name, result)
  File "D:\Personal projects\Imperial_Lottery\.venv\Lib\site-packages\telebot\apihelper.py", line 195, in _check_result
    raise ApiTelegramException(method_name, result, result_json)
telebot.apihelper.ApiTelegramException: A request to the Telegram API was unsuccessful. Error code: 409. Description: Conflict: terminated by other getUpdates request; make sure that only one bot instance is running

2025-06-16 17:22:23,314 - TeleBot - ERROR - Threaded polling exception: A request to the Telegram API was unsuccessful. Error code: 409. Description: Conflict: terminated by other getUpdates request; make sure that only one bot instance is running
2025-06-16 17:22:23,315 - TeleBot - ERROR - Exception traceback:
Traceback (most recent call last):
  File "D:\Personal projects\Imperial_Lottery\.venv\Lib\site-packages\telebot\__init__.py", line 1234, in __threaded_polling
    polling_thread.raise_exceptions()
    ~~~~~~~~~~~~~~~~~~~~~~~~~~~~~~~^^
  File "D:\Personal projects\Imperial_Lottery\.venv\Lib\site-packages\telebot\util.py", line 111, in raise_exceptions
    raise self.exception_info
  File "D:\Personal projects\Imperial_Lottery\.venv\Lib\site-packages\telebot\util.py", line 93, in run
    task(*args, **kwargs)
    ~~~~^^^^^^^^^^^^^^^^^
  File "D:\Personal projects\Imperial_Lottery\.venv\Lib\site-packages\telebot\__init__.py", line 688, in __retrieve_updates
    updates = self.get_updates(offset=(self.last_update_id + 1),
                               allowed_updates=allowed_updates,
                               timeout=timeout, long_polling_timeout=long_polling_timeout)
  File "D:\Personal projects\Imperial_Lottery\.venv\Lib\site-packages\telebot\__init__.py", line 660, in get_updates
    json_updates = apihelper.get_updates(
        self.token, offset=offset, limit=limit, timeout=timeout, allowed_updates=allowed_updates,
        long_polling_timeout=long_polling_timeout)
  File "D:\Personal projects\Imperial_Lottery\.venv\Lib\site-packages\telebot\apihelper.py", line 332, in get_updates
    return _make_request(token, method_url, params=payload)
  File "D:\Personal projects\Imperial_Lottery\.venv\Lib\site-packages\telebot\apihelper.py", line 168, in _make_request
    json_result = _check_result(method_name, result)
  File "D:\Personal projects\Imperial_Lottery\.venv\Lib\site-packages\telebot\apihelper.py", line 195, in _check_result
    raise ApiTelegramException(method_name, result, result_json)
telebot.apihelper.ApiTelegramException: A request to the Telegram API was unsuccessful. Error code: 409. Description: Conflict: terminated by other getUpdates request; make sure that only one bot instance is running

2025-06-16 17:22:31,342 - root - INFO - Логирование успешно настроено
2025-06-16 17:22:31,342 - root - INFO - Бот запущен
2025-06-16 17:22:31,343 - root - INFO - Бот запущен
2025-06-16 17:22:31,542 - root - ERROR - ConnectionError: ('Connection aborted.', ConnectionResetError(10054, 'Удаленный хост принудительно разорвал существующее подключение', None, 10054, None))
2025-06-16 17:22:51,543 - root - INFO - Бот запущен
2025-06-16 17:22:51,924 - TeleBot - ERROR - Threaded polling exception: A request to the Telegram API was unsuccessful. Error code: 409. Description: Conflict: terminated by other getUpdates request; make sure that only one bot instance is running
2025-06-16 17:22:51,925 - TeleBot - ERROR - Exception traceback:
Traceback (most recent call last):
  File "D:\Personal projects\Imperial_Lottery\.venv\Lib\site-packages\telebot\__init__.py", line 1234, in __threaded_polling
    polling_thread.raise_exceptions()
    ~~~~~~~~~~~~~~~~~~~~~~~~~~~~~~~^^
  File "D:\Personal projects\Imperial_Lottery\.venv\Lib\site-packages\telebot\util.py", line 111, in raise_exceptions
    raise self.exception_info
  File "D:\Personal projects\Imperial_Lottery\.venv\Lib\site-packages\telebot\util.py", line 93, in run
    task(*args, **kwargs)
    ~~~~^^^^^^^^^^^^^^^^^
  File "D:\Personal projects\Imperial_Lottery\.venv\Lib\site-packages\telebot\__init__.py", line 688, in __retrieve_updates
    updates = self.get_updates(offset=(self.last_update_id + 1),
                               allowed_updates=allowed_updates,
                               timeout=timeout, long_polling_timeout=long_polling_timeout)
  File "D:\Personal projects\Imperial_Lottery\.venv\Lib\site-packages\telebot\__init__.py", line 660, in get_updates
    json_updates = apihelper.get_updates(
        self.token, offset=offset, limit=limit, timeout=timeout, allowed_updates=allowed_updates,
        long_polling_timeout=long_polling_timeout)
  File "D:\Personal projects\Imperial_Lottery\.venv\Lib\site-packages\telebot\apihelper.py", line 332, in get_updates
    return _make_request(token, method_url, params=payload)
  File "D:\Personal projects\Imperial_Lottery\.venv\Lib\site-packages\telebot\apihelper.py", line 168, in _make_request
    json_result = _check_result(method_name, result)
  File "D:\Personal projects\Imperial_Lottery\.venv\Lib\site-packages\telebot\apihelper.py", line 195, in _check_result
    raise ApiTelegramException(method_name, result, result_json)
telebot.apihelper.ApiTelegramException: A request to the Telegram API was unsuccessful. Error code: 409. Description: Conflict: terminated by other getUpdates request; make sure that only one bot instance is running

2025-06-16 17:22:55,244 - TeleBot - ERROR - Threaded polling exception: A request to the Telegram API was unsuccessful. Error code: 409. Description: Conflict: terminated by other getUpdates request; make sure that only one bot instance is running
2025-06-16 17:22:55,246 - TeleBot - ERROR - Exception traceback:
Traceback (most recent call last):
  File "D:\Personal projects\Imperial_Lottery\.venv\Lib\site-packages\telebot\__init__.py", line 1234, in __threaded_polling
    polling_thread.raise_exceptions()
    ~~~~~~~~~~~~~~~~~~~~~~~~~~~~~~~^^
  File "D:\Personal projects\Imperial_Lottery\.venv\Lib\site-packages\telebot\util.py", line 111, in raise_exceptions
    raise self.exception_info
  File "D:\Personal projects\Imperial_Lottery\.venv\Lib\site-packages\telebot\util.py", line 93, in run
    task(*args, **kwargs)
    ~~~~^^^^^^^^^^^^^^^^^
  File "D:\Personal projects\Imperial_Lottery\.venv\Lib\site-packages\telebot\__init__.py", line 688, in __retrieve_updates
    updates = self.get_updates(offset=(self.last_update_id + 1),
                               allowed_updates=allowed_updates,
                               timeout=timeout, long_polling_timeout=long_polling_timeout)
  File "D:\Personal projects\Imperial_Lottery\.venv\Lib\site-packages\telebot\__init__.py", line 660, in get_updates
    json_updates = apihelper.get_updates(
        self.token, offset=offset, limit=limit, timeout=timeout, allowed_updates=allowed_updates,
        long_polling_timeout=long_polling_timeout)
  File "D:\Personal projects\Imperial_Lottery\.venv\Lib\site-packages\telebot\apihelper.py", line 332, in get_updates
    return _make_request(token, method_url, params=payload)
  File "D:\Personal projects\Imperial_Lottery\.venv\Lib\site-packages\telebot\apihelper.py", line 168, in _make_request
    json_result = _check_result(method_name, result)
  File "D:\Personal projects\Imperial_Lottery\.venv\Lib\site-packages\telebot\apihelper.py", line 195, in _check_result
    raise ApiTelegramException(method_name, result, result_json)
telebot.apihelper.ApiTelegramException: A request to the Telegram API was unsuccessful. Error code: 409. Description: Conflict: terminated by other getUpdates request; make sure that only one bot instance is running

2025-06-16 17:22:55,565 - TeleBot - ERROR - Threaded polling exception: A request to the Telegram API was unsuccessful. Error code: 409. Description: Conflict: terminated by other getUpdates request; make sure that only one bot instance is running
2025-06-16 17:22:55,566 - TeleBot - ERROR - Exception traceback:
Traceback (most recent call last):
  File "D:\Personal projects\Imperial_Lottery\.venv\Lib\site-packages\telebot\__init__.py", line 1234, in __threaded_polling
    polling_thread.raise_exceptions()
    ~~~~~~~~~~~~~~~~~~~~~~~~~~~~~~~^^
  File "D:\Personal projects\Imperial_Lottery\.venv\Lib\site-packages\telebot\util.py", line 111, in raise_exceptions
    raise self.exception_info
  File "D:\Personal projects\Imperial_Lottery\.venv\Lib\site-packages\telebot\util.py", line 93, in run
    task(*args, **kwargs)
    ~~~~^^^^^^^^^^^^^^^^^
  File "D:\Personal projects\Imperial_Lottery\.venv\Lib\site-packages\telebot\__init__.py", line 688, in __retrieve_updates
    updates = self.get_updates(offset=(self.last_update_id + 1),
                               allowed_updates=allowed_updates,
                               timeout=timeout, long_polling_timeout=long_polling_timeout)
  File "D:\Personal projects\Imperial_Lottery\.venv\Lib\site-packages\telebot\__init__.py", line 660, in get_updates
    json_updates = apihelper.get_updates(
        self.token, offset=offset, limit=limit, timeout=timeout, allowed_updates=allowed_updates,
        long_polling_timeout=long_polling_timeout)
  File "D:\Personal projects\Imperial_Lottery\.venv\Lib\site-packages\telebot\apihelper.py", line 332, in get_updates
    return _make_request(token, method_url, params=payload)
  File "D:\Personal projects\Imperial_Lottery\.venv\Lib\site-packages\telebot\apihelper.py", line 168, in _make_request
    json_result = _check_result(method_name, result)
  File "D:\Personal projects\Imperial_Lottery\.venv\Lib\site-packages\telebot\apihelper.py", line 195, in _check_result
    raise ApiTelegramException(method_name, result, result_json)
telebot.apihelper.ApiTelegramException: A request to the Telegram API was unsuccessful. Error code: 409. Description: Conflict: terminated by other getUpdates request; make sure that only one bot instance is running

2025-06-16 17:22:59,136 - TeleBot - ERROR - Threaded polling exception: A request to the Telegram API was unsuccessful. Error code: 409. Description: Conflict: terminated by other getUpdates request; make sure that only one bot instance is running
2025-06-16 17:22:59,137 - TeleBot - ERROR - Exception traceback:
Traceback (most recent call last):
  File "D:\Personal projects\Imperial_Lottery\.venv\Lib\site-packages\telebot\__init__.py", line 1234, in __threaded_polling
    polling_thread.raise_exceptions()
    ~~~~~~~~~~~~~~~~~~~~~~~~~~~~~~~^^
  File "D:\Personal projects\Imperial_Lottery\.venv\Lib\site-packages\telebot\util.py", line 111, in raise_exceptions
    raise self.exception_info
  File "D:\Personal projects\Imperial_Lottery\.venv\Lib\site-packages\telebot\util.py", line 93, in run
    task(*args, **kwargs)
    ~~~~^^^^^^^^^^^^^^^^^
  File "D:\Personal projects\Imperial_Lottery\.venv\Lib\site-packages\telebot\__init__.py", line 688, in __retrieve_updates
    updates = self.get_updates(offset=(self.last_update_id + 1),
                               allowed_updates=allowed_updates,
                               timeout=timeout, long_polling_timeout=long_polling_timeout)
  File "D:\Personal projects\Imperial_Lottery\.venv\Lib\site-packages\telebot\__init__.py", line 660, in get_updates
    json_updates = apihelper.get_updates(
        self.token, offset=offset, limit=limit, timeout=timeout, allowed_updates=allowed_updates,
        long_polling_timeout=long_polling_timeout)
  File "D:\Personal projects\Imperial_Lottery\.venv\Lib\site-packages\telebot\apihelper.py", line 332, in get_updates
    return _make_request(token, method_url, params=payload)
  File "D:\Personal projects\Imperial_Lottery\.venv\Lib\site-packages\telebot\apihelper.py", line 168, in _make_request
    json_result = _check_result(method_name, result)
  File "D:\Personal projects\Imperial_Lottery\.venv\Lib\site-packages\telebot\apihelper.py", line 195, in _check_result
    raise ApiTelegramException(method_name, result, result_json)
telebot.apihelper.ApiTelegramException: A request to the Telegram API was unsuccessful. Error code: 409. Description: Conflict: terminated by other getUpdates request; make sure that only one bot instance is running

2025-06-16 17:22:59,704 - TeleBot - ERROR - Threaded polling exception: A request to the Telegram API was unsuccessful. Error code: 409. Description: Conflict: terminated by other getUpdates request; make sure that only one bot instance is running
2025-06-16 17:22:59,705 - TeleBot - ERROR - Exception traceback:
Traceback (most recent call last):
  File "D:\Personal projects\Imperial_Lottery\.venv\Lib\site-packages\telebot\__init__.py", line 1234, in __threaded_polling
    polling_thread.raise_exceptions()
    ~~~~~~~~~~~~~~~~~~~~~~~~~~~~~~~^^
  File "D:\Personal projects\Imperial_Lottery\.venv\Lib\site-packages\telebot\util.py", line 111, in raise_exceptions
    raise self.exception_info
  File "D:\Personal projects\Imperial_Lottery\.venv\Lib\site-packages\telebot\util.py", line 93, in run
    task(*args, **kwargs)
    ~~~~^^^^^^^^^^^^^^^^^
  File "D:\Personal projects\Imperial_Lottery\.venv\Lib\site-packages\telebot\__init__.py", line 688, in __retrieve_updates
    updates = self.get_updates(offset=(self.last_update_id + 1),
                               allowed_updates=allowed_updates,
                               timeout=timeout, long_polling_timeout=long_polling_timeout)
  File "D:\Personal projects\Imperial_Lottery\.venv\Lib\site-packages\telebot\__init__.py", line 660, in get_updates
    json_updates = apihelper.get_updates(
        self.token, offset=offset, limit=limit, timeout=timeout, allowed_updates=allowed_updates,
        long_polling_timeout=long_polling_timeout)
  File "D:\Personal projects\Imperial_Lottery\.venv\Lib\site-packages\telebot\apihelper.py", line 332, in get_updates
    return _make_request(token, method_url, params=payload)
  File "D:\Personal projects\Imperial_Lottery\.venv\Lib\site-packages\telebot\apihelper.py", line 168, in _make_request
    json_result = _check_result(method_name, result)
  File "D:\Personal projects\Imperial_Lottery\.venv\Lib\site-packages\telebot\apihelper.py", line 195, in _check_result
    raise ApiTelegramException(method_name, result, result_json)
telebot.apihelper.ApiTelegramException: A request to the Telegram API was unsuccessful. Error code: 409. Description: Conflict: terminated by other getUpdates request; make sure that only one bot instance is running

2025-06-16 17:23:23,322 - TeleBot - ERROR - Threaded polling exception: A request to the Telegram API was unsuccessful. Error code: 409. Description: Conflict: terminated by other getUpdates request; make sure that only one bot instance is running
2025-06-16 17:23:23,323 - TeleBot - ERROR - Exception traceback:
Traceback (most recent call last):
  File "D:\Personal projects\Imperial_Lottery\.venv\Lib\site-packages\telebot\__init__.py", line 1234, in __threaded_polling
    polling_thread.raise_exceptions()
    ~~~~~~~~~~~~~~~~~~~~~~~~~~~~~~~^^
  File "D:\Personal projects\Imperial_Lottery\.venv\Lib\site-packages\telebot\util.py", line 111, in raise_exceptions
    raise self.exception_info
  File "D:\Personal projects\Imperial_Lottery\.venv\Lib\site-packages\telebot\util.py", line 93, in run
    task(*args, **kwargs)
    ~~~~^^^^^^^^^^^^^^^^^
  File "D:\Personal projects\Imperial_Lottery\.venv\Lib\site-packages\telebot\__init__.py", line 688, in __retrieve_updates
    updates = self.get_updates(offset=(self.last_update_id + 1),
                               allowed_updates=allowed_updates,
                               timeout=timeout, long_polling_timeout=long_polling_timeout)
  File "D:\Personal projects\Imperial_Lottery\.venv\Lib\site-packages\telebot\__init__.py", line 660, in get_updates
    json_updates = apihelper.get_updates(
        self.token, offset=offset, limit=limit, timeout=timeout, allowed_updates=allowed_updates,
        long_polling_timeout=long_polling_timeout)
  File "D:\Personal projects\Imperial_Lottery\.venv\Lib\site-packages\telebot\apihelper.py", line 332, in get_updates
    return _make_request(token, method_url, params=payload)
  File "D:\Personal projects\Imperial_Lottery\.venv\Lib\site-packages\telebot\apihelper.py", line 168, in _make_request
    json_result = _check_result(method_name, result)
  File "D:\Personal projects\Imperial_Lottery\.venv\Lib\site-packages\telebot\apihelper.py", line 195, in _check_result
    raise ApiTelegramException(method_name, result, result_json)
telebot.apihelper.ApiTelegramException: A request to the Telegram API was unsuccessful. Error code: 409. Description: Conflict: terminated by other getUpdates request; make sure that only one bot instance is running

2025-06-16 17:23:26,642 - TeleBot - ERROR - Threaded polling exception: A request to the Telegram API was unsuccessful. Error code: 409. Description: Conflict: terminated by other getUpdates request; make sure that only one bot instance is running
2025-06-16 17:23:26,642 - TeleBot - ERROR - Exception traceback:
Traceback (most recent call last):
  File "D:\Personal projects\Imperial_Lottery\.venv\Lib\site-packages\telebot\__init__.py", line 1234, in __threaded_polling
    polling_thread.raise_exceptions()
    ~~~~~~~~~~~~~~~~~~~~~~~~~~~~~~~^^
  File "D:\Personal projects\Imperial_Lottery\.venv\Lib\site-packages\telebot\util.py", line 111, in raise_exceptions
    raise self.exception_info
  File "D:\Personal projects\Imperial_Lottery\.venv\Lib\site-packages\telebot\util.py", line 93, in run
    task(*args, **kwargs)
    ~~~~^^^^^^^^^^^^^^^^^
  File "D:\Personal projects\Imperial_Lottery\.venv\Lib\site-packages\telebot\__init__.py", line 688, in __retrieve_updates
    updates = self.get_updates(offset=(self.last_update_id + 1),
                               allowed_updates=allowed_updates,
                               timeout=timeout, long_polling_timeout=long_polling_timeout)
  File "D:\Personal projects\Imperial_Lottery\.venv\Lib\site-packages\telebot\__init__.py", line 660, in get_updates
    json_updates = apihelper.get_updates(
        self.token, offset=offset, limit=limit, timeout=timeout, allowed_updates=allowed_updates,
        long_polling_timeout=long_polling_timeout)
  File "D:\Personal projects\Imperial_Lottery\.venv\Lib\site-packages\telebot\apihelper.py", line 332, in get_updates
    return _make_request(token, method_url, params=payload)
  File "D:\Personal projects\Imperial_Lottery\.venv\Lib\site-packages\telebot\apihelper.py", line 168, in _make_request
    json_result = _check_result(method_name, result)
  File "D:\Personal projects\Imperial_Lottery\.venv\Lib\site-packages\telebot\apihelper.py", line 195, in _check_result
    raise ApiTelegramException(method_name, result, result_json)
telebot.apihelper.ApiTelegramException: A request to the Telegram API was unsuccessful. Error code: 409. Description: Conflict: terminated by other getUpdates request; make sure that only one bot instance is running

2025-06-16 17:24:26,703 - TeleBot - ERROR - Threaded polling exception: A request to the Telegram API was unsuccessful. Error code: 409. Description: Conflict: terminated by other getUpdates request; make sure that only one bot instance is running
2025-06-16 17:24:26,704 - TeleBot - ERROR - Exception traceback:
Traceback (most recent call last):
  File "D:\Personal projects\Imperial_Lottery\.venv\Lib\site-packages\telebot\__init__.py", line 1234, in __threaded_polling
    polling_thread.raise_exceptions()
    ~~~~~~~~~~~~~~~~~~~~~~~~~~~~~~~^^
  File "D:\Personal projects\Imperial_Lottery\.venv\Lib\site-packages\telebot\util.py", line 111, in raise_exceptions
    raise self.exception_info
  File "D:\Personal projects\Imperial_Lottery\.venv\Lib\site-packages\telebot\util.py", line 93, in run
    task(*args, **kwargs)
    ~~~~^^^^^^^^^^^^^^^^^
  File "D:\Personal projects\Imperial_Lottery\.venv\Lib\site-packages\telebot\__init__.py", line 688, in __retrieve_updates
    updates = self.get_updates(offset=(self.last_update_id + 1),
                               allowed_updates=allowed_updates,
                               timeout=timeout, long_polling_timeout=long_polling_timeout)
  File "D:\Personal projects\Imperial_Lottery\.venv\Lib\site-packages\telebot\__init__.py", line 660, in get_updates
    json_updates = apihelper.get_updates(
        self.token, offset=offset, limit=limit, timeout=timeout, allowed_updates=allowed_updates,
        long_polling_timeout=long_polling_timeout)
  File "D:\Personal projects\Imperial_Lottery\.venv\Lib\site-packages\telebot\apihelper.py", line 332, in get_updates
    return _make_request(token, method_url, params=payload)
  File "D:\Personal projects\Imperial_Lottery\.venv\Lib\site-packages\telebot\apihelper.py", line 168, in _make_request
    json_result = _check_result(method_name, result)
  File "D:\Personal projects\Imperial_Lottery\.venv\Lib\site-packages\telebot\apihelper.py", line 195, in _check_result
    raise ApiTelegramException(method_name, result, result_json)
telebot.apihelper.ApiTelegramException: A request to the Telegram API was unsuccessful. Error code: 409. Description: Conflict: terminated by other getUpdates request; make sure that only one bot instance is running

2025-06-16 17:24:30,016 - TeleBot - ERROR - Threaded polling exception: A request to the Telegram API was unsuccessful. Error code: 409. Description: Conflict: terminated by other getUpdates request; make sure that only one bot instance is running
2025-06-16 17:24:30,017 - TeleBot - ERROR - Exception traceback:
Traceback (most recent call last):
  File "D:\Personal projects\Imperial_Lottery\.venv\Lib\site-packages\telebot\__init__.py", line 1234, in __threaded_polling
    polling_thread.raise_exceptions()
    ~~~~~~~~~~~~~~~~~~~~~~~~~~~~~~~^^
  File "D:\Personal projects\Imperial_Lottery\.venv\Lib\site-packages\telebot\util.py", line 111, in raise_exceptions
    raise self.exception_info
  File "D:\Personal projects\Imperial_Lottery\.venv\Lib\site-packages\telebot\util.py", line 93, in run
    task(*args, **kwargs)
    ~~~~^^^^^^^^^^^^^^^^^
  File "D:\Personal projects\Imperial_Lottery\.venv\Lib\site-packages\telebot\__init__.py", line 688, in __retrieve_updates
    updates = self.get_updates(offset=(self.last_update_id + 1),
                               allowed_updates=allowed_updates,
                               timeout=timeout, long_polling_timeout=long_polling_timeout)
  File "D:\Personal projects\Imperial_Lottery\.venv\Lib\site-packages\telebot\__init__.py", line 660, in get_updates
    json_updates = apihelper.get_updates(
        self.token, offset=offset, limit=limit, timeout=timeout, allowed_updates=allowed_updates,
        long_polling_timeout=long_polling_timeout)
  File "D:\Personal projects\Imperial_Lottery\.venv\Lib\site-packages\telebot\apihelper.py", line 332, in get_updates
    return _make_request(token, method_url, params=payload)
  File "D:\Personal projects\Imperial_Lottery\.venv\Lib\site-packages\telebot\apihelper.py", line 168, in _make_request
    json_result = _check_result(method_name, result)
  File "D:\Personal projects\Imperial_Lottery\.venv\Lib\site-packages\telebot\apihelper.py", line 195, in _check_result
    raise ApiTelegramException(method_name, result, result_json)
telebot.apihelper.ApiTelegramException: A request to the Telegram API was unsuccessful. Error code: 409. Description: Conflict: terminated by other getUpdates request; make sure that only one bot instance is running

2025-06-16 17:24:36,484 - root - INFO - Логирование успешно настроено
2025-06-16 17:24:36,484 - root - INFO - Бот запущен
2025-06-16 17:24:36,484 - root - INFO - Бот запущен
2025-06-16 17:24:36,720 - root - ERROR - ConnectionError: ('Connection aborted.', ConnectionResetError(10054, 'Удаленный хост принудительно разорвал существующее подключение', None, 10054, None))
2025-06-16 17:24:56,721 - root - INFO - Бот запущен
2025-06-16 17:24:57,114 - TeleBot - ERROR - Threaded polling exception: A request to the Telegram API was unsuccessful. Error code: 409. Description: Conflict: terminated by other getUpdates request; make sure that only one bot instance is running
2025-06-16 17:24:57,115 - TeleBot - ERROR - Exception traceback:
Traceback (most recent call last):
  File "D:\Personal projects\Imperial_Lottery\.venv\Lib\site-packages\telebot\__init__.py", line 1234, in __threaded_polling
    polling_thread.raise_exceptions()
    ~~~~~~~~~~~~~~~~~~~~~~~~~~~~~~~^^
  File "D:\Personal projects\Imperial_Lottery\.venv\Lib\site-packages\telebot\util.py", line 111, in raise_exceptions
    raise self.exception_info
  File "D:\Personal projects\Imperial_Lottery\.venv\Lib\site-packages\telebot\util.py", line 93, in run
    task(*args, **kwargs)
    ~~~~^^^^^^^^^^^^^^^^^
  File "D:\Personal projects\Imperial_Lottery\.venv\Lib\site-packages\telebot\__init__.py", line 688, in __retrieve_updates
    updates = self.get_updates(offset=(self.last_update_id + 1),
                               allowed_updates=allowed_updates,
                               timeout=timeout, long_polling_timeout=long_polling_timeout)
  File "D:\Personal projects\Imperial_Lottery\.venv\Lib\site-packages\telebot\__init__.py", line 660, in get_updates
    json_updates = apihelper.get_updates(
        self.token, offset=offset, limit=limit, timeout=timeout, allowed_updates=allowed_updates,
        long_polling_timeout=long_polling_timeout)
  File "D:\Personal projects\Imperial_Lottery\.venv\Lib\site-packages\telebot\apihelper.py", line 332, in get_updates
    return _make_request(token, method_url, params=payload)
  File "D:\Personal projects\Imperial_Lottery\.venv\Lib\site-packages\telebot\apihelper.py", line 168, in _make_request
    json_result = _check_result(method_name, result)
  File "D:\Personal projects\Imperial_Lottery\.venv\Lib\site-packages\telebot\apihelper.py", line 195, in _check_result
    raise ApiTelegramException(method_name, result, result_json)
telebot.apihelper.ApiTelegramException: A request to the Telegram API was unsuccessful. Error code: 409. Description: Conflict: terminated by other getUpdates request; make sure that only one bot instance is running

2025-06-16 17:25:00,436 - TeleBot - ERROR - Threaded polling exception: A request to the Telegram API was unsuccessful. Error code: 409. Description: Conflict: terminated by other getUpdates request; make sure that only one bot instance is running
2025-06-16 17:25:00,437 - TeleBot - ERROR - Exception traceback:
Traceback (most recent call last):
  File "D:\Personal projects\Imperial_Lottery\.venv\Lib\site-packages\telebot\__init__.py", line 1234, in __threaded_polling
    polling_thread.raise_exceptions()
    ~~~~~~~~~~~~~~~~~~~~~~~~~~~~~~~^^
  File "D:\Personal projects\Imperial_Lottery\.venv\Lib\site-packages\telebot\util.py", line 111, in raise_exceptions
    raise self.exception_info
  File "D:\Personal projects\Imperial_Lottery\.venv\Lib\site-packages\telebot\util.py", line 93, in run
    task(*args, **kwargs)
    ~~~~^^^^^^^^^^^^^^^^^
  File "D:\Personal projects\Imperial_Lottery\.venv\Lib\site-packages\telebot\__init__.py", line 688, in __retrieve_updates
    updates = self.get_updates(offset=(self.last_update_id + 1),
                               allowed_updates=allowed_updates,
                               timeout=timeout, long_polling_timeout=long_polling_timeout)
  File "D:\Personal projects\Imperial_Lottery\.venv\Lib\site-packages\telebot\__init__.py", line 660, in get_updates
    json_updates = apihelper.get_updates(
        self.token, offset=offset, limit=limit, timeout=timeout, allowed_updates=allowed_updates,
        long_polling_timeout=long_polling_timeout)
  File "D:\Personal projects\Imperial_Lottery\.venv\Lib\site-packages\telebot\apihelper.py", line 332, in get_updates
    return _make_request(token, method_url, params=payload)
  File "D:\Personal projects\Imperial_Lottery\.venv\Lib\site-packages\telebot\apihelper.py", line 168, in _make_request
    json_result = _check_result(method_name, result)
  File "D:\Personal projects\Imperial_Lottery\.venv\Lib\site-packages\telebot\apihelper.py", line 195, in _check_result
    raise ApiTelegramException(method_name, result, result_json)
telebot.apihelper.ApiTelegramException: A request to the Telegram API was unsuccessful. Error code: 409. Description: Conflict: terminated by other getUpdates request; make sure that only one bot instance is running

2025-06-16 17:25:00,765 - TeleBot - ERROR - Threaded polling exception: A request to the Telegram API was unsuccessful. Error code: 409. Description: Conflict: terminated by other getUpdates request; make sure that only one bot instance is running
2025-06-16 17:25:00,766 - TeleBot - ERROR - Exception traceback:
Traceback (most recent call last):
  File "D:\Personal projects\Imperial_Lottery\.venv\Lib\site-packages\telebot\__init__.py", line 1234, in __threaded_polling
    polling_thread.raise_exceptions()
    ~~~~~~~~~~~~~~~~~~~~~~~~~~~~~~~^^
  File "D:\Personal projects\Imperial_Lottery\.venv\Lib\site-packages\telebot\util.py", line 111, in raise_exceptions
    raise self.exception_info
  File "D:\Personal projects\Imperial_Lottery\.venv\Lib\site-packages\telebot\util.py", line 93, in run
    task(*args, **kwargs)
    ~~~~^^^^^^^^^^^^^^^^^
  File "D:\Personal projects\Imperial_Lottery\.venv\Lib\site-packages\telebot\__init__.py", line 688, in __retrieve_updates
    updates = self.get_updates(offset=(self.last_update_id + 1),
                               allowed_updates=allowed_updates,
                               timeout=timeout, long_polling_timeout=long_polling_timeout)
  File "D:\Personal projects\Imperial_Lottery\.venv\Lib\site-packages\telebot\__init__.py", line 660, in get_updates
    json_updates = apihelper.get_updates(
        self.token, offset=offset, limit=limit, timeout=timeout, allowed_updates=allowed_updates,
        long_polling_timeout=long_polling_timeout)
  File "D:\Personal projects\Imperial_Lottery\.venv\Lib\site-packages\telebot\apihelper.py", line 332, in get_updates
    return _make_request(token, method_url, params=payload)
  File "D:\Personal projects\Imperial_Lottery\.venv\Lib\site-packages\telebot\apihelper.py", line 168, in _make_request
    json_result = _check_result(method_name, result)
  File "D:\Personal projects\Imperial_Lottery\.venv\Lib\site-packages\telebot\apihelper.py", line 195, in _check_result
    raise ApiTelegramException(method_name, result, result_json)
telebot.apihelper.ApiTelegramException: A request to the Telegram API was unsuccessful. Error code: 409. Description: Conflict: terminated by other getUpdates request; make sure that only one bot instance is running

2025-06-16 17:25:04,338 - TeleBot - ERROR - Threaded polling exception: A request to the Telegram API was unsuccessful. Error code: 409. Description: Conflict: terminated by other getUpdates request; make sure that only one bot instance is running
2025-06-16 17:25:04,339 - TeleBot - ERROR - Exception traceback:
Traceback (most recent call last):
  File "D:\Personal projects\Imperial_Lottery\.venv\Lib\site-packages\telebot\__init__.py", line 1234, in __threaded_polling
    polling_thread.raise_exceptions()
    ~~~~~~~~~~~~~~~~~~~~~~~~~~~~~~~^^
  File "D:\Personal projects\Imperial_Lottery\.venv\Lib\site-packages\telebot\util.py", line 111, in raise_exceptions
    raise self.exception_info
  File "D:\Personal projects\Imperial_Lottery\.venv\Lib\site-packages\telebot\util.py", line 93, in run
    task(*args, **kwargs)
    ~~~~^^^^^^^^^^^^^^^^^
  File "D:\Personal projects\Imperial_Lottery\.venv\Lib\site-packages\telebot\__init__.py", line 688, in __retrieve_updates
    updates = self.get_updates(offset=(self.last_update_id + 1),
                               allowed_updates=allowed_updates,
                               timeout=timeout, long_polling_timeout=long_polling_timeout)
  File "D:\Personal projects\Imperial_Lottery\.venv\Lib\site-packages\telebot\__init__.py", line 660, in get_updates
    json_updates = apihelper.get_updates(
        self.token, offset=offset, limit=limit, timeout=timeout, allowed_updates=allowed_updates,
        long_polling_timeout=long_polling_timeout)
  File "D:\Personal projects\Imperial_Lottery\.venv\Lib\site-packages\telebot\apihelper.py", line 332, in get_updates
    return _make_request(token, method_url, params=payload)
  File "D:\Personal projects\Imperial_Lottery\.venv\Lib\site-packages\telebot\apihelper.py", line 168, in _make_request
    json_result = _check_result(method_name, result)
  File "D:\Personal projects\Imperial_Lottery\.venv\Lib\site-packages\telebot\apihelper.py", line 195, in _check_result
    raise ApiTelegramException(method_name, result, result_json)
telebot.apihelper.ApiTelegramException: A request to the Telegram API was unsuccessful. Error code: 409. Description: Conflict: terminated by other getUpdates request; make sure that only one bot instance is running

2025-06-16 17:25:04,907 - TeleBot - ERROR - Threaded polling exception: A request to the Telegram API was unsuccessful. Error code: 409. Description: Conflict: terminated by other getUpdates request; make sure that only one bot instance is running
2025-06-16 17:25:04,908 - TeleBot - ERROR - Exception traceback:
Traceback (most recent call last):
  File "D:\Personal projects\Imperial_Lottery\.venv\Lib\site-packages\telebot\__init__.py", line 1234, in __threaded_polling
    polling_thread.raise_exceptions()
    ~~~~~~~~~~~~~~~~~~~~~~~~~~~~~~~^^
  File "D:\Personal projects\Imperial_Lottery\.venv\Lib\site-packages\telebot\util.py", line 111, in raise_exceptions
    raise self.exception_info
  File "D:\Personal projects\Imperial_Lottery\.venv\Lib\site-packages\telebot\util.py", line 93, in run
    task(*args, **kwargs)
    ~~~~^^^^^^^^^^^^^^^^^
  File "D:\Personal projects\Imperial_Lottery\.venv\Lib\site-packages\telebot\__init__.py", line 688, in __retrieve_updates
    updates = self.get_updates(offset=(self.last_update_id + 1),
                               allowed_updates=allowed_updates,
                               timeout=timeout, long_polling_timeout=long_polling_timeout)
  File "D:\Personal projects\Imperial_Lottery\.venv\Lib\site-packages\telebot\__init__.py", line 660, in get_updates
    json_updates = apihelper.get_updates(
        self.token, offset=offset, limit=limit, timeout=timeout, allowed_updates=allowed_updates,
        long_polling_timeout=long_polling_timeout)
  File "D:\Personal projects\Imperial_Lottery\.venv\Lib\site-packages\telebot\apihelper.py", line 332, in get_updates
    return _make_request(token, method_url, params=payload)
  File "D:\Personal projects\Imperial_Lottery\.venv\Lib\site-packages\telebot\apihelper.py", line 168, in _make_request
    json_result = _check_result(method_name, result)
  File "D:\Personal projects\Imperial_Lottery\.venv\Lib\site-packages\telebot\apihelper.py", line 195, in _check_result
    raise ApiTelegramException(method_name, result, result_json)
telebot.apihelper.ApiTelegramException: A request to the Telegram API was unsuccessful. Error code: 409. Description: Conflict: terminated by other getUpdates request; make sure that only one bot instance is running

2025-06-16 17:25:08,970 - TeleBot - ERROR - Threaded polling exception: A request to the Telegram API was unsuccessful. Error code: 409. Description: Conflict: terminated by other getUpdates request; make sure that only one bot instance is running
2025-06-16 17:25:08,971 - TeleBot - ERROR - Exception traceback:
Traceback (most recent call last):
  File "D:\Personal projects\Imperial_Lottery\.venv\Lib\site-packages\telebot\__init__.py", line 1234, in __threaded_polling
    polling_thread.raise_exceptions()
    ~~~~~~~~~~~~~~~~~~~~~~~~~~~~~~~^^
  File "D:\Personal projects\Imperial_Lottery\.venv\Lib\site-packages\telebot\util.py", line 111, in raise_exceptions
    raise self.exception_info
  File "D:\Personal projects\Imperial_Lottery\.venv\Lib\site-packages\telebot\util.py", line 93, in run
    task(*args, **kwargs)
    ~~~~^^^^^^^^^^^^^^^^^
  File "D:\Personal projects\Imperial_Lottery\.venv\Lib\site-packages\telebot\__init__.py", line 688, in __retrieve_updates
    updates = self.get_updates(offset=(self.last_update_id + 1),
                               allowed_updates=allowed_updates,
                               timeout=timeout, long_polling_timeout=long_polling_timeout)
  File "D:\Personal projects\Imperial_Lottery\.venv\Lib\site-packages\telebot\__init__.py", line 660, in get_updates
    json_updates = apihelper.get_updates(
        self.token, offset=offset, limit=limit, timeout=timeout, allowed_updates=allowed_updates,
        long_polling_timeout=long_polling_timeout)
  File "D:\Personal projects\Imperial_Lottery\.venv\Lib\site-packages\telebot\apihelper.py", line 332, in get_updates
    return _make_request(token, method_url, params=payload)
  File "D:\Personal projects\Imperial_Lottery\.venv\Lib\site-packages\telebot\apihelper.py", line 168, in _make_request
    json_result = _check_result(method_name, result)
  File "D:\Personal projects\Imperial_Lottery\.venv\Lib\site-packages\telebot\apihelper.py", line 195, in _check_result
    raise ApiTelegramException(method_name, result, result_json)
telebot.apihelper.ApiTelegramException: A request to the Telegram API was unsuccessful. Error code: 409. Description: Conflict: terminated by other getUpdates request; make sure that only one bot instance is running

2025-06-16 17:25:10,036 - TeleBot - ERROR - Threaded polling exception: A request to the Telegram API was unsuccessful. Error code: 409. Description: Conflict: terminated by other getUpdates request; make sure that only one bot instance is running
2025-06-16 17:25:10,037 - TeleBot - ERROR - Exception traceback:
Traceback (most recent call last):
  File "D:\Personal projects\Imperial_Lottery\.venv\Lib\site-packages\telebot\__init__.py", line 1234, in __threaded_polling
    polling_thread.raise_exceptions()
    ~~~~~~~~~~~~~~~~~~~~~~~~~~~~~~~^^
  File "D:\Personal projects\Imperial_Lottery\.venv\Lib\site-packages\telebot\util.py", line 111, in raise_exceptions
    raise self.exception_info
  File "D:\Personal projects\Imperial_Lottery\.venv\Lib\site-packages\telebot\util.py", line 93, in run
    task(*args, **kwargs)
    ~~~~^^^^^^^^^^^^^^^^^
  File "D:\Personal projects\Imperial_Lottery\.venv\Lib\site-packages\telebot\__init__.py", line 688, in __retrieve_updates
    updates = self.get_updates(offset=(self.last_update_id + 1),
                               allowed_updates=allowed_updates,
                               timeout=timeout, long_polling_timeout=long_polling_timeout)
  File "D:\Personal projects\Imperial_Lottery\.venv\Lib\site-packages\telebot\__init__.py", line 660, in get_updates
    json_updates = apihelper.get_updates(
        self.token, offset=offset, limit=limit, timeout=timeout, allowed_updates=allowed_updates,
        long_polling_timeout=long_polling_timeout)
  File "D:\Personal projects\Imperial_Lottery\.venv\Lib\site-packages\telebot\apihelper.py", line 332, in get_updates
    return _make_request(token, method_url, params=payload)
  File "D:\Personal projects\Imperial_Lottery\.venv\Lib\site-packages\telebot\apihelper.py", line 168, in _make_request
    json_result = _check_result(method_name, result)
  File "D:\Personal projects\Imperial_Lottery\.venv\Lib\site-packages\telebot\apihelper.py", line 195, in _check_result
    raise ApiTelegramException(method_name, result, result_json)
telebot.apihelper.ApiTelegramException: A request to the Telegram API was unsuccessful. Error code: 409. Description: Conflict: terminated by other getUpdates request; make sure that only one bot instance is running

2025-06-16 17:25:30,082 - TeleBot - ERROR - Threaded polling exception: A request to the Telegram API was unsuccessful. Error code: 409. Description: Conflict: terminated by other getUpdates request; make sure that only one bot instance is running
2025-06-16 17:25:30,083 - TeleBot - ERROR - Exception traceback:
Traceback (most recent call last):
  File "D:\Personal projects\Imperial_Lottery\.venv\Lib\site-packages\telebot\__init__.py", line 1234, in __threaded_polling
    polling_thread.raise_exceptions()
    ~~~~~~~~~~~~~~~~~~~~~~~~~~~~~~~^^
  File "D:\Personal projects\Imperial_Lottery\.venv\Lib\site-packages\telebot\util.py", line 111, in raise_exceptions
    raise self.exception_info
  File "D:\Personal projects\Imperial_Lottery\.venv\Lib\site-packages\telebot\util.py", line 93, in run
    task(*args, **kwargs)
    ~~~~^^^^^^^^^^^^^^^^^
  File "D:\Personal projects\Imperial_Lottery\.venv\Lib\site-packages\telebot\__init__.py", line 688, in __retrieve_updates
    updates = self.get_updates(offset=(self.last_update_id + 1),
                               allowed_updates=allowed_updates,
                               timeout=timeout, long_polling_timeout=long_polling_timeout)
  File "D:\Personal projects\Imperial_Lottery\.venv\Lib\site-packages\telebot\__init__.py", line 660, in get_updates
    json_updates = apihelper.get_updates(
        self.token, offset=offset, limit=limit, timeout=timeout, allowed_updates=allowed_updates,
        long_polling_timeout=long_polling_timeout)
  File "D:\Personal projects\Imperial_Lottery\.venv\Lib\site-packages\telebot\apihelper.py", line 332, in get_updates
    return _make_request(token, method_url, params=payload)
  File "D:\Personal projects\Imperial_Lottery\.venv\Lib\site-packages\telebot\apihelper.py", line 168, in _make_request
    json_result = _check_result(method_name, result)
  File "D:\Personal projects\Imperial_Lottery\.venv\Lib\site-packages\telebot\apihelper.py", line 195, in _check_result
    raise ApiTelegramException(method_name, result, result_json)
telebot.apihelper.ApiTelegramException: A request to the Telegram API was unsuccessful. Error code: 409. Description: Conflict: terminated by other getUpdates request; make sure that only one bot instance is running

2025-06-16 17:25:33,404 - TeleBot - ERROR - Threaded polling exception: A request to the Telegram API was unsuccessful. Error code: 409. Description: Conflict: terminated by other getUpdates request; make sure that only one bot instance is running
2025-06-16 17:25:33,405 - TeleBot - ERROR - Exception traceback:
Traceback (most recent call last):
  File "D:\Personal projects\Imperial_Lottery\.venv\Lib\site-packages\telebot\__init__.py", line 1234, in __threaded_polling
    polling_thread.raise_exceptions()
    ~~~~~~~~~~~~~~~~~~~~~~~~~~~~~~~^^
  File "D:\Personal projects\Imperial_Lottery\.venv\Lib\site-packages\telebot\util.py", line 111, in raise_exceptions
    raise self.exception_info
  File "D:\Personal projects\Imperial_Lottery\.venv\Lib\site-packages\telebot\util.py", line 93, in run
    task(*args, **kwargs)
    ~~~~^^^^^^^^^^^^^^^^^
  File "D:\Personal projects\Imperial_Lottery\.venv\Lib\site-packages\telebot\__init__.py", line 688, in __retrieve_updates
    updates = self.get_updates(offset=(self.last_update_id + 1),
                               allowed_updates=allowed_updates,
                               timeout=timeout, long_polling_timeout=long_polling_timeout)
  File "D:\Personal projects\Imperial_Lottery\.venv\Lib\site-packages\telebot\__init__.py", line 660, in get_updates
    json_updates = apihelper.get_updates(
        self.token, offset=offset, limit=limit, timeout=timeout, allowed_updates=allowed_updates,
        long_polling_timeout=long_polling_timeout)
  File "D:\Personal projects\Imperial_Lottery\.venv\Lib\site-packages\telebot\apihelper.py", line 332, in get_updates
    return _make_request(token, method_url, params=payload)
  File "D:\Personal projects\Imperial_Lottery\.venv\Lib\site-packages\telebot\apihelper.py", line 168, in _make_request
    json_result = _check_result(method_name, result)
  File "D:\Personal projects\Imperial_Lottery\.venv\Lib\site-packages\telebot\apihelper.py", line 195, in _check_result
    raise ApiTelegramException(method_name, result, result_json)
telebot.apihelper.ApiTelegramException: A request to the Telegram API was unsuccessful. Error code: 409. Description: Conflict: terminated by other getUpdates request; make sure that only one bot instance is running

2025-06-16 17:26:37,152 - root - INFO - Логирование успешно настроено
2025-06-16 17:26:37,153 - root - INFO - Бот запущен
2025-06-16 17:26:37,153 - root - INFO - Бот запущен
2025-06-16 17:26:37,874 - root - ERROR - ConnectionError: ('Connection aborted.', ConnectionResetError(10054, 'Удаленный хост принудительно разорвал существующее подключение', None, 10054, None))
2025-06-16 17:27:04,257 - root - INFO - Логирование успешно настроено
2025-06-16 17:27:04,257 - root - INFO - Бот запущен
2025-06-16 17:27:04,257 - root - INFO - Бот запущен
2025-06-16 17:53:30,800 - root - INFO - Логирование успешно настроено
2025-06-16 17:53:30,800 - root - INFO - Бот запущен
2025-06-16 17:53:30,800 - root - INFO - Бот запущен
2025-06-16 17:53:39,044 - root - INFO - Бот запущен
2025-06-16 17:54:06,511 - root - ERROR - Other error: 'NoneType' object is not subscriptable
2025-06-16 17:54:27,973 - root - INFO - Логирование успешно настроено
2025-06-16 17:54:27,973 - root - INFO - Бот запущен
2025-06-16 17:54:27,973 - root - INFO - Бот запущен
2025-06-16 17:54:28,161 - root - ERROR - ConnectionError: ('Connection aborted.', ConnectionResetError(10054, 'Удаленный хост принудительно разорвал существующее подключение', None, 10054, None))
2025-06-16 17:54:41,117 - root - INFO - Логирование успешно настроено
2025-06-16 17:54:41,117 - root - INFO - Бот запущен
2025-06-16 17:54:41,117 - root - INFO - Бот запущен
2025-06-16 17:54:41,317 - root - ERROR - ConnectionError: ('Connection aborted.', ConnectionResetError(10054, 'Удаленный хост принудительно разорвал существующее подключение', None, 10054, None))
2025-06-16 17:55:01,318 - root - INFO - Бот запущен
2025-06-16 17:55:01,827 - root - ERROR - Other error: 'NoneType' object is not subscriptable
2025-06-16 17:55:21,829 - root - INFO - Бот запущен
2025-06-16 17:55:21,830 - root - ERROR - Other error: 'NoneType' object is not subscriptable
2025-06-16 17:55:25,499 - root - INFO - Логирование успешно настроено
2025-06-16 17:55:25,499 - root - INFO - Бот запущен
2025-06-16 17:55:25,499 - root - INFO - Бот запущен
2025-06-16 17:55:25,878 - root - ERROR - ConnectionError: ('Connection aborted.', ConnectionResetError(10054, 'Удаленный хост принудительно разорвал существующее подключение', None, 10054, None))
2025-06-16 17:55:51,117 - root - INFO - Логирование успешно настроено
2025-06-16 17:55:51,117 - root - INFO - Бот запущен
2025-06-16 17:55:51,117 - root - INFO - Бот запущен
2025-06-16 17:55:51,310 - root - ERROR - ConnectionError: ('Connection aborted.', ConnectionResetError(10054, 'Удаленный хост принудительно разорвал существующее подключение', None, 10054, None))
2025-06-16 17:56:11,311 - root - INFO - Бот запущен
2025-06-16 17:56:11,767 - root - ERROR - Other error: 'NoneType' object is not subscriptable
2025-06-16 17:56:31,768 - root - INFO - Бот запущен
2025-06-16 17:56:31,768 - root - ERROR - Other error: 'NoneType' object is not subscriptable
2025-06-16 17:56:42,772 - root - INFO - Логирование успешно настроено
2025-06-16 17:56:42,773 - root - INFO - Бот запущен
2025-06-16 17:56:42,773 - root - INFO - Бот запущен
2025-06-16 17:56:43,176 - root - ERROR - ConnectionError: ('Connection aborted.', ConnectionResetError(10054, 'Удаленный хост принудительно разорвал существующее подключение', None, 10054, None))
2025-06-16 17:57:03,177 - root - INFO - Бот запущен
2025-06-16 17:57:03,510 - root - ERROR - Other error: 'NoneType' object is not subscriptable
2025-06-16 17:57:15,921 - root - INFO - Логирование успешно настроено
2025-06-16 17:57:15,921 - root - INFO - Бот запущен
2025-06-16 17:57:15,921 - root - INFO - Бот запущен
2025-06-16 17:57:16,300 - root - ERROR - ConnectionError: ('Connection aborted.', ConnectionResetError(10054, 'Удаленный хост принудительно разорвал существующее подключение', None, 10054, None))
2025-06-16 17:57:36,300 - root - INFO - Бот запущен
2025-06-16 17:57:36,527 - root - ERROR - Other error: 'NoneType' object is not subscriptable
2025-06-16 17:57:56,528 - root - INFO - Бот запущен
2025-06-16 17:58:16,912 - root - INFO - Логирование успешно настроено
2025-06-16 17:58:16,912 - root - INFO - Бот запущен
2025-06-16 17:58:16,912 - root - INFO - Бот запущен
2025-06-16 17:58:35,184 - root - ERROR - Other error: 'NoneType' object is not subscriptable
2025-06-16 17:58:50,185 - root - INFO - Бот запущен
2025-06-16 18:02:29,511 - root - INFO - Логирование успешно настроено
2025-06-16 18:02:29,511 - root - INFO - Бот запущен
2025-06-16 18:02:29,511 - root - INFO - Бот запущен
2025-06-16 18:02:35,163 - root - INFO - Логирование успешно настроено
2025-06-16 18:02:35,163 - root - INFO - Бот запущен
2025-06-16 18:02:35,163 - root - INFO - Бот запущен
2025-06-16 18:02:37,609 - root - ERROR - ConnectionError: ('Connection aborted.', ConnectionResetError(10054, 'Удаленный хост принудительно разорвал существующее подключение', None, 10054, None))
2025-06-16 18:02:57,610 - root - INFO - Бот запущен
2025-06-16 18:03:30,827 - root - INFO - Бот запущен
2025-06-16 18:08:31,772 - root - ERROR - Other error: 'NoneType' object is not subscriptable
2025-06-16 18:08:42,249 - root - INFO - Логирование успешно настроено
2025-06-16 18:08:42,249 - root - INFO - Бот запущен
2025-06-16 18:08:42,249 - root - INFO - Бот запущен
2025-06-16 18:08:42,492 - root - ERROR - ConnectionError: ('Connection aborted.', ConnectionResetError(10054, 'Удаленный хост принудительно разорвал существующее подключение', None, 10054, None))
2025-06-16 18:08:46,934 - root - INFO - Логирование успешно настроено
2025-06-16 18:08:46,934 - root - INFO - Бот запущен
2025-06-16 18:08:46,934 - root - INFO - Бот запущен
2025-06-16 18:22:41,520 - root - ERROR - ConnectionError: ('Connection aborted.', ConnectionResetError(10054, 'Удаленный хост принудительно разорвал существующее подключение', None, 10054, None))
2025-06-16 18:52:56,821 - root - INFO - Бот запущен
2025-06-16 18:52:56,854 - root - ERROR - ConnectionError: HTTPSConnectionPool(host='api.telegram.org', port=443): Max retries exceeded with url: /bot8067610575:AAFjG0nG-vXZPZGlLMjXK_X_QyuuaG8gJvs/getUpdates?offset=225678811&timeout=20 (Caused by NameResolutionError("<urllib3.connection.HTTPSConnection object at 0x000001F23172C410>: Failed to resolve 'api.telegram.org' ([Errno 11001] getaddrinfo failed)"))
2025-06-16 19:27:19,998 - root - INFO - Бот запущен
2025-06-16 19:59:41,191 - root - INFO - Логирование успешно настроено
2025-06-16 19:59:41,191 - root - INFO - Бот запущен
2025-06-16 20:44:15,122 - root - ERROR - ConnectionError: ('Connection aborted.', ConnectionResetError(10054, 'Удаленный хост принудительно разорвал существующее подключение', None, 10054, None))
2025-06-16 20:44:31,123 - root - INFO - Бот запущен
2025-06-16 21:09:58,262 - root - INFO - Логирование успешно настроено
2025-06-16 21:09:58,262 - root - INFO - Бот запущен
2025-06-16 21:24:38,344 - root - INFO - Логирование успешно настроено
2025-06-16 21:24:38,344 - root - INFO - Бот запущен
2025-06-16 21:40:52,935 - root - INFO - Логирование успешно настроено
2025-06-16 21:40:52,935 - root - INFO - Бот запущен
2025-06-16 21:41:03,088 - root - ERROR - Other error: add_coins_to_user() missing 1 required positional argument: 'promo_code'
2025-06-16 21:41:14,089 - root - INFO - Бот запущен
2025-06-16 21:41:24,297 - root - ERROR - Other error: add_coins_to_user() missing 1 required positional argument: 'promo_code'
2025-06-16 21:41:36,298 - root - INFO - Бот запущен
2025-06-16 21:41:45,508 - root - ERROR - Other error: add_coins_to_user() missing 1 required positional argument: 'promo_code'
2025-06-16 21:41:59,509 - root - INFO - Бот запущен
2025-06-16 21:48:31,522 - root - INFO - Логирование успешно настроено
2025-06-16 21:48:31,522 - root - INFO - Бот запущен
2025-06-16 21:48:37,479 - root - ERROR - Other error: 'NoneType' object is not subscriptable
2025-06-16 21:48:48,480 - root - INFO - Бот запущен
2025-06-16 21:54:05,779 - root - ERROR - Other error: 'NoneType' object is not subscriptable
2025-06-16 21:54:17,781 - root - INFO - Бот запущен
2025-06-16 21:57:30,706 - root - INFO - Логирование успешно настроено
2025-06-16 21:57:30,706 - root - INFO - Бот запущен
2025-06-16 21:58:15,595 - root - ERROR - Other error: 'NoneType' object is not subscriptable
2025-06-16 21:58:26,596 - root - INFO - Бот запущен
2025-06-16 21:58:41,629 - root - ERROR - Other error: 'NoneType' object is not subscriptable
2025-06-16 21:58:53,630 - root - INFO - Бот запущен
